Workbook
Name cfgStartHdr: 'Guide'!$C$20
Name cfgLWDHdr: 'Guide'!$C$21
Name cfgTypeHdr: 'Guide'!$C$22
Name cfgStatusHdr: 'Guide'!$C$23
Name cfgIDHdr: 'Guide'!$C$24
Name FiltCat: 'Dashboard'!$C$5
Name FiltPeriod: 'Dashboard'!$E$5
Name P_ID: INDEX('Data_Profile'!$A$5:$AZ$5004,0,MATCH(cfgIDHdr,'Data_Profile'!$4:$4,0))
Name P_Start: INDEX('Data_Profile'!$A$5:$AZ$5004,0,MATCH(cfgStartHdr,'Data_Profile'!$4:$4,0))
Name P_LWD: INDEX('Data_Profile'!$A$5:$AZ$5004,0,MATCH(cfgLWDHdr,'Data_Profile'!$4:$4,0))
Name P_Type: INDEX('Data_Profile'!$A$5:$AZ$5004,0,MATCH(cfgTypeHdr,'Data_Profile'!$4:$4,0))
Name P_Status: INDEX('Data_Profile'!$A$5:$AZ$5004,0,MATCH(cfgStatusHdr,'Data_Profile'!$4:$4,0))
Name L_ID: INDEX('Data_Leavers'!$A$5:$AZ$5004,0,MATCH(cfgIDHdr,'Data_Leavers'!$4:$4,0))
Name L_Start: INDEX('Data_Leavers'!$A$5:$AZ$5004,0,MATCH(cfgStartHdr,'Data_Leavers'!$4:$4,0))
Name L_LWD: INDEX('Data_Leavers'!$A$5:$AZ$5004,0,MATCH(cfgLWDHdr,'Data_Leavers'!$4:$4,0))
Name L_Type: INDEX('Data_Leavers'!$A$5:$AZ$5004,0,MATCH(cfgTypeHdr,'Data_Leavers'!$4:$4,0))
Name L_Status: INDEX('Data_Leavers'!$A$5:$AZ$5004,0,MATCH(cfgStatusHdr,'Data_Leavers'!$4:$4,0))
Name L_InP: 'Calc'!$A$5:$A$5004
Name P_TypeN: 'Calc'!$B$5:$B$5004
Name L_TypeN: 'Calc'!$D$5:$D$5004
Name P_StatusN: 'Calc'!$E$5:$E$5004
Name L_StatusN: 'Calc'!$G$5:$G$5004
Name L_TwinIna: 'Calc'!$J$5:$J$5004
Name PeriodList: 'Calc'!$F$5:$F$58
Name SelStart: 'Calc'!$K$2
Name SelEnd: 'Calc'!$K$3
Name SelStartTxt: IF('Calc'!$K$2="","",TEXT('Calc'!$K$2,"yyyy-mm"))
Name SelEndTxt: IF('Calc'!$K$3="","",TEXT('Calc'!$K$3,"yyyy-mm"))

Sheet Dashboard
B2: IBGT Department Turnover Dashboard
B3: =IF('Calc'!$H$2+'Calc'!$I$2>0,"⚠ Header mapping broken - open the Guide sheet and check C20:C24","Data source: Data_Profile "&TEXT(SUMPRODUCT(--(P_ID<>"")),"0")&" rows | Data_Leavers "&TEXT(SUMPRODUCT(--(L_ID<>"")),"0")&" rows | "&IF('Calc'!$C$5="","No data yet - paste data and it updates automatically",TEXT('Calc'!$C$5,"yyyy-mm")&" onward, 48 months"))
B5: Type Filter | C5: All | D5: Period | E5: All | G5: Switch type and period - cards update instantly; headcount is measured at the end of the selected period, joiners & leavers within it
B7: Period-End Headcount | E7: Joiners in Period | H7: Leavers in Period | K7: Data Coverage
B8: =IF('Calc'!$H$2+'Calc'!$I$2>0,"Fix header mapping",IF('Calc'!$C$5="","-",IF('Calc'!$K$3="",SUMPRODUCT((P_StatusN="ACTIVE")*(ISNUMBER(P_Start))*(P_Start<=TODAY())*((P_TypeN=UPPER(FiltCat))+(FiltCat="All")))+SUMPRODUCT((L_StatusN="ACTIVE")*(ISNUMBER(L_Start))*(L_Start<=TODAY())*((L_TypeN=UPPER(FiltCat))+(FiltCat="All")))-SUMPRODUCT((L_StatusN="ACTIVE")*(ISNUMBER(L_Start))*(L_Start<=TODAY())*((L_TypeN=UPPER(FiltCat))+(FiltCat="All"))*(L_InP=1)),SUMPRODUCT((ISNUMBER(P_Start))*(P_Start<=EOMONTH('Calc'!$K$3,0))*(((P_StatusN="ACTIVE")+((ISNUMBER(P_LWD))*(P_LWD>=EOMONTH('Calc'!$K$3,0))))>0)*((P_TypeN=UPPER(FiltCat))+(FiltCat="All")))+SUMPRODUCT((ISNUMBER(L_Start))*(L_Start<=EOMONTH('Calc'!$K$3,0))*(((L_StatusN="ACTIVE")+((ISNUMBER(L_LWD))*(L_LWD>=EOMONTH('Calc'!$K$3,0))))>0)*((L_TypeN=UPPER(FiltCat))+(FiltCat="All")))-SUMPRODUCT((ISNUMBER(L_Start))*(L_Start<=EOMONTH('Calc'!$K$3,0))*(((L_StatusN="ACTIVE")+((ISNUMBER(L_LWD))*(L_LWD>=EOMONTH('Calc'!$K$3,0))))>0)*((L_TypeN=UPPER(FiltCat))+(FiltCat="All"))*(L_InP=1))))) | E8: =IF('Calc'!$H$2+'Calc'!$I$2>0,"Fix header mapping",IF('Calc'!$C$5="","-",IF('Calc'!$K$3="",SUM('Monthly Detail'!$H$5:$H$52),SUMPRODUCT((ISNUMBER(P_Start))*(P_Start>=SelStart)*(P_Start<=SelEnd)*((P_TypeN=UPPER(FiltCat))+(FiltCat="All")))+SUMPRODUCT((ISNUMBER(L_Start))*(L_Start>=SelStart)*(L_Start<=SelEnd)*((L_TypeN=UPPER(FiltCat))+(FiltCat="All")))-SUMPRODUCT((ISNUMBER(L_Start))*(L_Start>=SelStart)*(L_Start<=SelEnd)*((L_TypeN=UPPER(FiltCat))+(FiltCat="All"))*(L_InP=1))))) | H8: =IF('Calc'!$H$2+'Calc'!$I$2>0,"Fix header mapping",IF('Calc'!$C$5="","-",IF('Calc'!$K$3="",SUMPRODUCT((P_StatusN="INACTIVE")*((P_TypeN=UPPER(FiltCat))+(FiltCat="All")))+SUMPRODUCT((L_StatusN="INACTIVE")*((L_TypeN=UPPER(FiltCat))+(FiltCat="All")))-SUMPRODUCT((L_StatusN="INACTIVE")*((L_TypeN=UPPER(FiltCat))+(FiltCat="All"))*(L_InP=1)*(L_TwinIna=1)),SUMPRODUCT((P_StatusN="INACTIVE")*(ISNUMBER(P_LWD))*(P_LWD>=SelStart)*(P_LWD<=SelEnd)*((P_TypeN=UPPER(FiltCat))+(FiltCat="All")))+SUMPRODUCT((L_StatusN="INACTIVE")*(ISNUMBER(L_LWD))*(L_LWD>=SelStart)*(L_LWD<=SelEnd)*((L_TypeN=UPPER(FiltCat))+(FiltCat="All")))-SUMPRODUCT((L_StatusN="INACTIVE")*(ISNUMBER(L_LWD))*(L_LWD>=SelStart)*(L_LWD<=SelEnd)*((L_TypeN=UPPER(FiltCat))+(FiltCat="All"))*(L_InP=1)*(L_TwinIna=1))))) | K8: =IF('Calc'!$H$2+'Calc'!$I$2>0,"Fix header mapping",IF('Calc'!$C$5="","-",TEXT(MAX(P_Start,P_LWD,L_Start,L_LWD),"yyyy-mm")))
B10: Headcount - Perm | E10: Headcount - PC | H10: Headcount - MS | K10: Latest Month Leavers
B11: =IF('Calc'!$H$2+'Calc'!$I$2>0,"Fix header mapping",IF('Calc'!$C$5="","-",IF('Calc'!$K$3="",SUMPRODUCT((P_StatusN="ACTIVE")*(ISNUMBER(P_Start))*(P_Start<=TODAY())*((P_TypeN="PERM")))+SUMPRODUCT((L_StatusN="ACTIVE")*(ISNUMBER(L_Start))*(L_Start<=TODAY())*((L_TypeN="PERM")))-SUMPRODUCT((L_StatusN="ACTIVE")*(ISNUMBER(L_Start))*(L_Start<=TODAY())*((L_TypeN="PERM"))*(L_InP=1)),SUMPRODUCT((ISNUMBER(P_Start))*(P_Start<=EOMONTH('Calc'!$K$3,0))*(((P_StatusN="ACTIVE")+((ISNUMBER(P_LWD))*(P_LWD>=EOMONTH('Calc'!$K$3,0))))>0)*((P_TypeN="PERM")))+SUMPRODUCT((ISNUMBER(L_Start))*(L_Start<=EOMONTH('Calc'!$K$3,0))*(((L_StatusN="ACTIVE")+((ISNUMBER(L_LWD))*(L_LWD>=EOMONTH('Calc'!$K$3,0))))>0)*((L_TypeN="PERM")))-SUMPRODUCT((ISNUMBER(L_Start))*(L_Start<=EOMONTH('Calc'!$K$3,0))*(((L_StatusN="ACTIVE")+((ISNUMBER(L_LWD))*(L_LWD>=EOMONTH('Calc'!$K$3,0))))>0)*((L_TypeN="PERM"))*(L_InP=1))))) | E11: =IF('Calc'!$H$2+'Calc'!$I$2>0,"Fix header mapping",IF('Calc'!$C$5="","-",IF('Calc'!$K$3="",SUMPRODUCT((P_StatusN="ACTIVE")*(ISNUMBER(P_Start))*(P_Start<=TODAY())*((P_TypeN="PC")))+SUMPRODUCT((L_StatusN="ACTIVE")*(ISNUMBER(L_Start))*(L_Start<=TODAY())*((L_TypeN="PC")))-SUMPRODUCT((L_StatusN="ACTIVE")*(ISNUMBER(L_Start))*(L_Start<=TODAY())*((L_TypeN="PC"))*(L_InP=1)),SUMPRODUCT((ISNUMBER(P_Start))*(P_Start<=EOMONTH('Calc'!$K$3,0))*(((P_StatusN="ACTIVE")+((ISNUMBER(P_LWD))*(P_LWD>=EOMONTH('Calc'!$K$3,0))))>0)*((P_TypeN="PC")))+SUMPRODUCT((ISNUMBER(L_Start))*(L_Start<=EOMONTH('Calc'!$K$3,0))*(((L_StatusN="ACTIVE")+((ISNUMBER(L_LWD))*(L_LWD>=EOMONTH('Calc'!$K$3,0))))>0)*((L_TypeN="PC")))-SUMPRODUCT((ISNUMBER(L_Start))*(L_Start<=EOMONTH('Calc'!$K$3,0))*(((L_StatusN="ACTIVE")+((ISNUMBER(L_LWD))*(L_LWD>=EOMONTH('Calc'!$K$3,0))))>0)*((L_TypeN="PC"))*(L_InP=1))))) | H11: =IF('Calc'!$H$2+'Calc'!$I$2>0,"Fix header mapping",IF('Calc'!$C$5="","-",IF('Calc'!$K$3="",SUMPRODUCT((P_StatusN="ACTIVE")*(ISNUMBER(P_Start))*(P_Start<=TODAY())*((P_TypeN="MS")))+SUMPRODUCT((L_StatusN="ACTIVE")*(ISNUMBER(L_Start))*(L_Start<=TODAY())*((L_TypeN="MS")))-SUMPRODUCT((L_StatusN="ACTIVE")*(ISNUMBER(L_Start))*(L_Start<=TODAY())*((L_TypeN="MS"))*(L_InP=1)),SUMPRODUCT((ISNUMBER(P_Start))*(P_Start<=EOMONTH('Calc'!$K$3,0))*(((P_StatusN="ACTIVE")+((ISNUMBER(P_LWD))*(P_LWD>=EOMONTH('Calc'!$K$3,0))))>0)*((P_TypeN="MS")))+SUMPRODUCT((ISNUMBER(L_Start))*(L_Start<=EOMONTH('Calc'!$K$3,0))*(((L_StatusN="ACTIVE")+((ISNUMBER(L_LWD))*(L_LWD>=EOMONTH('Calc'!$K$3,0))))>0)*((L_TypeN="MS")))-SUMPRODUCT((ISNUMBER(L_Start))*(L_Start<=EOMONTH('Calc'!$K$3,0))*(((L_StatusN="ACTIVE")+((ISNUMBER(L_LWD))*(L_LWD>=EOMONTH('Calc'!$K$3,0))))>0)*((L_TypeN="MS"))*(L_InP=1))))) | K11: =IF('Calc'!$H$2+'Calc'!$I$2>0,"Fix header mapping",IF('Calc'!$C$5="","-",IFERROR(INDEX('Monthly Detail'!$D$5:$D$52,MATCH(DATE(YEAR(MAX(P_LWD,L_LWD)),MONTH(MAX(P_LWD,L_LWD)),1),'Calc'!$C$5:$C$52,0)),"-")))
K33: Data Overview
K34: ="Data_Profile rows: "&TEXT(SUMPRODUCT(--(P_ID<>"")),"0")&" | Data_Leavers rows: "&TEXT(SUMPRODUCT(--(L_ID<>"")),"0")
K35: ="Profile rows with Last Work Day (leavers): "&TEXT(SUMPRODUCT((P_ID<>"")*ISNUMBER(P_LWD)),"0")
K36: ="Leavers also present in Profile (auto-deduplicated): "&TEXT(SUMPRODUCT(--(L_InP=1)),"0")
K37: =IFERROR("Date anomalies: Profile "&TEXT(SUMPRODUCT((P_ID<>"")*(P_Start<>"")*(ISNUMBER(P_Start)=FALSE)),"0")&" start / "&TEXT(SUMPRODUCT((P_ID<>"")*(P_LWD<>"")*(ISNUMBER(P_LWD)=FALSE)),"0")&" LWD | "&"Leavers "&TEXT(SUMPRODUCT((L_ID<>"")*(L_Start<>"")*(ISNUMBER(L_Start)=FALSE)),"0")&" / "&TEXT(SUMPRODUCT((L_ID<>"")*(L_LWD<>"")*(ISNUMBER(L_LWD)=FALSE)),"0")&" LWD","Pending header mapping fix")
K38: ="Inactive rows without Last Work Day (cannot be placed in a month): "&TEXT(SUMPRODUCT((P_StatusN="INACTIVE")*(P_LWD=""))+SUMPRODUCT((L_StatusN="INACTIVE")*(L_LWD="")),"0")
K39: ="Latest data month: "&IF('Calc'!$C$5="","-",TEXT(EOMONTH(MAX(P_Start,P_LWD,L_Start,L_LWD),0),"yyyy-mm"))
K40: Rules: an employee counts as active through their Last Work Day; Data_Leavers rows without Last Work Day are excluded from headcount; Contract End Date is reserved. See the Guide sheet.
B52: Paste data into Data_Profile / Data_Leavers and the dashboard recalculates automatically (Ctrl+Alt+F9 forces a full recalc). Calculation rules and header mapping: see the Guide sheet.

Sheet Monthly Detail
B2: Monthly Turnover Detail (linked to the Dashboard filter)
B3: Rules: Headcount EOM = employed at month end (the Last Work Day itself counts as an active day); Leavers = Status Inactive with Last Work Day in that month; Joiners = start date in that month. C/D/H follow the Dashboard filter; Perm/PC/MS columns always show the full breakdown; 48 months from the earliest start date.
B4: Month | C4: Headcount EOM (filtered) | D4: Leavers (filtered) | E4: Perm Leavers | F4: PC Leavers | G4: MS Leavers | H4: Joiners (filtered) | J4: Type | K4: Current Headcount
B5: =IF('Calc'!$H$2+'Calc'!$I$2>0,"",IF('Calc'!$C5="","",TEXT('Calc'!$C5,"yyyy-mm"))) | C5: =IF('Calc'!$H$2+'Calc'!$I$2>0,"",IF('Calc'!$C5="","",SUMPRODUCT((ISNUMBER(P_Start))*(P_Start<=EOMONTH('Calc'!$C5,0))*(((P_StatusN="ACTIVE")+((ISNUMBER(P_LWD))*(P_LWD>=EOMONTH('Calc'!$C5,0))))>0)*((P_TypeN=UPPER(FiltCat))+(FiltCat="All")))+SUMPRODUCT((ISNUMBER(L_Start))*(L_Start<=EOMONTH('Calc'!$C5,0))*(((L_StatusN="ACTIVE")+((ISNUMBER(L_LWD))*(L_LWD>=EOMONTH('Calc'!$C5,0))))>0)*((L_TypeN=UPPER(FiltCat))+(FiltCat="All")))-SUMPRODUCT((ISNUMBER(L_Start))*(L_Start<=EOMONTH('Calc'!$C5,0))*(((L_StatusN="ACTIVE")+((ISNUMBER(L_LWD))*(L_LWD>=EOMONTH('Calc'!$C5,0))))>0)*((L_TypeN=UPPER(FiltCat))+(FiltCat="All"))*(L_InP=1)))) | D5: =IF('Calc'!$H$2+'Calc'!$I$2>0,"",IF('Calc'!$C5="","",SUMPRODUCT((P_StatusN="INACTIVE")*(ISNUMBER(P_LWD))*(P_LWD>='Calc'!$C5)*(P_LWD<EDATE('Calc'!$C5,1))*((P_TypeN=UPPER(FiltCat))+(FiltCat="All")))+SUMPRODUCT((L_StatusN="INACTIVE")*(ISNUMBER(L_LWD))*(L_LWD>='Calc'!$C5)*(L_LWD<EDATE('Calc'!$C5,1))*((L_TypeN=UPPER(FiltCat))+(FiltCat="All")))-SUMPRODUCT((L_StatusN="INACTIVE")*(ISNUMBER(L_LWD))*(L_LWD>='Calc'!$C5)*(L_LWD<EDATE('Calc'!$C5,1))*((L_TypeN=UPPER(FiltCat))+(FiltCat="All"))*(L_InP=1)*(L_TwinIna=1)))) | E5: =IF('Calc'!$H$2+'Calc'!$I$2>0,"",IF('Calc'!$C5="","",SUMPRODUCT((P_StatusN="INACTIVE")*(ISNUMBER(P_LWD))*(P_LWD>='Calc'!$C5)*(P_LWD<EDATE('Calc'!$C5,1))*((P_TypeN="PERM")))+SUMPRODUCT((L_StatusN="INACTIVE")*(ISNUMBER(L_LWD))*(L_LWD>='Calc'!$C5)*(L_LWD<EDATE('Calc'!$C5,1))*((L_TypeN="PERM")))-SUMPRODUCT((L_StatusN="INACTIVE")*(ISNUMBER(L_LWD))*(L_LWD>='Calc'!$C5)*(L_LWD<EDATE('Calc'!$C5,1))*((L_TypeN="PERM"))*(L_InP=1)*(L_TwinIna=1)))) | F5: =IF('Calc'!$H$2+'Calc'!$I$2>0,"",IF('Calc'!$C5="","",SUMPRODUCT((P_StatusN="INACTIVE")*(ISNUMBER(P_LWD))*(P_LWD>='Calc'!$C5)*(P_LWD<EDATE('Calc'!$C5,1))*((P_TypeN="PC")))+SUMPRODUCT((L_StatusN="INACTIVE")*(ISNUMBER(L_LWD))*(L_LWD>='Calc'!$C5)*(L_LWD<EDATE('Calc'!$C5,1))*((L_TypeN="PC")))-SUMPRODUCT((L_StatusN="INACTIVE")*(ISNUMBER(L_LWD))*(L_LWD>='Calc'!$C5)*(L_LWD<EDATE('Calc'!$C5,1))*((L_TypeN="PC"))*(L_InP=1)*(L_TwinIna=1)))) | G5: =IF('Calc'!$H$2+'Calc'!$I$2>0,"",IF('Calc'!$C5="","",SUMPRODUCT((P_StatusN="INACTIVE")*(ISNUMBER(P_LWD))*(P_LWD>='Calc'!$C5)*(P_LWD<EDATE('Calc'!$C5,1))*((P_TypeN="MS")))+SUMPRODUCT((L_StatusN="INACTIVE")*(ISNUMBER(L_LWD))*(L_LWD>='Calc'!$C5)*(L_LWD<EDATE('Calc'!$C5,1))*((L_TypeN="MS")))-SUMPRODUCT((L_StatusN="INACTIVE")*(ISNUMBER(L_LWD))*(L_LWD>='Calc'!$C5)*(L_LWD<EDATE('Calc'!$C5,1))*((L_TypeN="MS"))*(L_InP=1)*(L_TwinIna=1)))) | H5: =IF('Calc'!$H$2+'Calc'!$I$2>0,"",IF('Calc'!$C5="","",SUMPRODUCT((ISNUMBER(P_Start))*(P_Start>='Calc'!$C5)*(P_Start<EDATE('Calc'!$C5,1))*((P_TypeN=UPPER(FiltCat))+(FiltCat="All")))+SUMPRODUCT((ISNUMBER(L_Start))*(L_Start>='Calc'!$C5)*(L_Start<EDATE('Calc'!$C5,1))*((L_TypeN=UPPER(FiltCat))+(FiltCat="All")))-SUMPRODUCT((ISNUMBER(L_Start))*(L_Start>='Calc'!$C5)*(L_Start<EDATE('Calc'!$C5,1))*((L_TypeN=UPPER(FiltCat))+(FiltCat="All"))*(L_InP=1)))) | J5: Perm | K5: ='Dashboard'!B$11
B6: =IF('Calc'!$H$2+'Calc'!$I$2>0,"",IF('Calc'!$C6="","",TEXT('Calc'!$C6,"yyyy-mm"))) | C6: =IF('Calc'!$H$2+'Calc'!$I$2>0,"",IF('Calc'!$C6="","",SUMPRODUCT((ISNUMBER(P_Start))*(P_Start<=EOMONTH('Calc'!$C6,0))*(((P_StatusN="ACTIVE")+((ISNUMBER(P_LWD))*(P_LWD>=EOMONTH('Calc'!$C6,0))))>0)*((P_TypeN=UPPER(FiltCat))+(FiltCat="All")))+SUMPRODUCT((ISNUMBER(L_Start))*(L_Start<=EOMONTH('Calc'!$C6,0))*(((L_StatusN="ACTIVE")+((ISNUMBER(L_LWD))*(L_LWD>=EOMONTH('Calc'!$C6,0))))>0)*((L_TypeN=UPPER(FiltCat))+(FiltCat="All")))-SUMPRODUCT((ISNUMBER(L_Start))*(L_Start<=EOMONTH('Calc'!$C6,0))*(((L_StatusN="ACTIVE")+((ISNUMBER(L_LWD))*(L_LWD>=EOMONTH('Calc'!$C6,0))))>0)*((L_TypeN=UPPER(FiltCat))+(FiltCat="All"))*(L_InP=1)))) | D6: =IF('Calc'!$H$2+'Calc'!$I$2>0,"",IF('Calc'!$C6="","",SUMPRODUCT((P_StatusN="INACTIVE")*(ISNUMBER(P_LWD))*(P_LWD>='Calc'!$C6)*(P_LWD<EDATE('Calc'!$C6,1))*((P_TypeN=UPPER(FiltCat))+(FiltCat="All")))+SUMPRODUCT((L_StatusN="INACTIVE")*(ISNUMBER(L_LWD))*(L_LWD>='Calc'!$C6)*(L_LWD<EDATE('Calc'!$C6,1))*((L_TypeN=UPPER(FiltCat))+(FiltCat="All")))-SUMPRODUCT((L_StatusN="INACTIVE")*(ISNUMBER(L_LWD))*(L_LWD>='Calc'!$C6)*(L_LWD<EDATE('Calc'!$C6,1))*((L_TypeN=UPPER(FiltCat))+(FiltCat="All"))*(L_InP=1)*(L_TwinIna=1)))) | E6: =IF('Calc'!$H$2+'Calc'!$I$2>0,"",IF('Calc'!$C6="","",SUMPRODUCT((P_StatusN="INACTIVE")*(ISNUMBER(P_LWD))*(P_LWD>='Calc'!$C6)*(P_LWD<EDATE('Calc'!$C6,1))*((P_TypeN="PERM")))+SUMPRODUCT((L_StatusN="INACTIVE")*(ISNUMBER(L_LWD))*(L_LWD>='Calc'!$C6)*(L_LWD<EDATE('Calc'!$C6,1))*((L_TypeN="PERM")))-SUMPRODUCT((L_StatusN="INACTIVE")*(ISNUMBER(L_LWD))*(L_LWD>='Calc'!$C6)*(L_LWD<EDATE('Calc'!$C6,1))*((L_TypeN="PERM"))*(L_InP=1)*(L_TwinIna=1)))) | F6: =IF('Calc'!$H$2+'Calc'!$I$2>0,"",IF('Calc'!$C6="","",SUMPRODUCT((P_StatusN="INACTIVE")*(ISNUMBER(P_LWD))*(P_LWD>='Calc'!$C6)*(P_LWD<EDATE('Calc'!$C6,1))*((P_TypeN="PC")))+SUMPRODUCT((L_StatusN="INACTIVE")*(ISNUMBER(L_LWD))*(L_LWD>='Calc'!$C6)*(L_LWD<EDATE('Calc'!$C6,1))*((L_TypeN="PC")))-SUMPRODUCT((L_StatusN="INACTIVE")*(ISNUMBER(L_LWD))*(L_LWD>='Calc'!$C6)*(L_LWD<EDATE('Calc'!$C6,1))*((L_TypeN="PC"))*(L_InP=1)*(L_TwinIna=1)))) | G6: =IF('Calc'!$H$2+'Calc'!$I$2>0,"",IF('Calc'!$C6="","",SUMPRODUCT((P_StatusN="INACTIVE")*(ISNUMBER(P_LWD))*(P_LWD>='Calc'!$C6)*(P_LWD<EDATE('Calc'!$C6,1))*((P_TypeN="MS")))+SUMPRODUCT((L_StatusN="INACTIVE")*(ISNUMBER(L_LWD))*(L_LWD>='Calc'!$C6)*(L_LWD<EDATE('Calc'!$C6,1))*((L_TypeN="MS")))-SUMPRODUCT((L_StatusN="INACTIVE")*(ISNUMBER(L_LWD))*(L_LWD>='Calc'!$C6)*(L_LWD<EDATE('Calc'!$C6,1))*((L_TypeN="MS"))*(L_InP=1)*(L_TwinIna=1)))) | H6: =IF('Calc'!$H$2+'Calc'!$I$2>0,"",IF('Calc'!$C6="","",SUMPRODUCT((ISNUMBER(P_Start))*(P_Start>='Calc'!$C6)*(P_Start<EDATE('Calc'!$C6,1))*((P_TypeN=UPPER(FiltCat))+(FiltCat="All")))+SUMPRODUCT((ISNUMBER(L_Start))*(L_Start>='Calc'!$C6)*(L_Start<EDATE('Calc'!$C6,1))*((L_TypeN=UPPER(FiltCat))+(FiltCat="All")))-SUMPRODUCT((ISNUMBER(L_Start))*(L_Start>='Calc'!$C6)*(L_Start<EDATE('Calc'!$C6,1))*((L_TypeN=UPPER(FiltCat))+(FiltCat="All"))*(L_InP=1)))) | J6: PC | K6: ='Dashboard'!E$11
B7: =IF('Calc'!$H$2+'Calc'!$I$2>0,"",IF('Calc'!$C7="","",TEXT('Calc'!$C7,"yyyy-mm"))) | C7: =IF('Calc'!$H$2+'Calc'!$I$2>0,"",IF('Calc'!$C7="","",SUMPRODUCT((ISNUMBER(P_Start))*(P_Start<=EOMONTH('Calc'!$C7,0))*(((P_StatusN="ACTIVE")+((ISNUMBER(P_LWD))*(P_LWD>=EOMONTH('Calc'!$C7,0))))>0)*((P_TypeN=UPPER(FiltCat))+(FiltCat="All")))+SUMPRODUCT((ISNUMBER(L_Start))*(L_Start<=EOMONTH('Calc'!$C7,0))*(((L_StatusN="ACTIVE")+((ISNUMBER(L_LWD))*(L_LWD>=EOMONTH('Calc'!$C7,0))))>0)*((L_TypeN=UPPER(FiltCat))+(FiltCat="All")))-SUMPRODUCT((ISNUMBER(L_Start))*(L_Start<=EOMONTH('Calc'!$C7,0))*(((L_StatusN="ACTIVE")+((ISNUMBER(L_LWD))*(L_LWD>=EOMONTH('Calc'!$C7,0))))>0)*((L_TypeN=UPPER(FiltCat))+(FiltCat="All"))*(L_InP=1)))) | D7: =IF('Calc'!$H$2+'Calc'!$I$2>0,"",IF('Calc'!$C7="","",SUMPRODUCT((P_StatusN="INACTIVE")*(ISNUMBER(P_LWD))*(P_LWD>='Calc'!$C7)*(P_LWD<EDATE('Calc'!$C7,1))*((P_TypeN=UPPER(FiltCat))+(FiltCat="All")))+SUMPRODUCT((L_StatusN="INACTIVE")*(ISNUMBER(L_LWD))*(L_LWD>='Calc'!$C7)*(L_LWD<EDATE('Calc'!$C7,1))*((L_TypeN=UPPER(FiltCat))+(FiltCat="All")))-SUMPRODUCT((L_StatusN="INACTIVE")*(ISNUMBER(L_LWD))*(L_LWD>='Calc'!$C7)*(L_LWD<EDATE('Calc'!$C7,1))*((L_TypeN=UPPER(FiltCat))+(FiltCat="All"))*(L_InP=1)*(L_TwinIna=1)))) | E7: =IF('Calc'!$H$2+'Calc'!$I$2>0,"",IF('Calc'!$C7="","",SUMPRODUCT((P_StatusN="INACTIVE")*(ISNUMBER(P_LWD))*(P_LWD>='Calc'!$C7)*(P_LWD<EDATE('Calc'!$C7,1))*((P_TypeN="PERM")))+SUMPRODUCT((L_StatusN="INACTIVE")*(ISNUMBER(L_LWD))*(L_LWD>='Calc'!$C7)*(L_LWD<EDATE('Calc'!$C7,1))*((L_TypeN="PERM")))-SUMPRODUCT((L_StatusN="INACTIVE")*(ISNUMBER(L_LWD))*(L_LWD>='Calc'!$C7)*(L_LWD<EDATE('Calc'!$C7,1))*((L_TypeN="PERM"))*(L_InP=1)*(L_TwinIna=1)))) | F7: =IF('Calc'!$H$2+'Calc'!$I$2>0,"",IF('Calc'!$C7="","",SUMPRODUCT((P_StatusN="INACTIVE")*(ISNUMBER(P_LWD))*(P_LWD>='Calc'!$C7)*(P_LWD<EDATE('Calc'!$C7,1))*((P_TypeN="PC")))+SUMPRODUCT((L_StatusN="INACTIVE")*(ISNUMBER(L_LWD))*(L_LWD>='Calc'!$C7)*(L_LWD<EDATE('Calc'!$C7,1))*((L_TypeN="PC")))-SUMPRODUCT((L_StatusN="INACTIVE")*(ISNUMBER(L_LWD))*(L_LWD>='Calc'!$C7)*(L_LWD<EDATE('Calc'!$C7,1))*((L_TypeN="PC"))*(L_InP=1)*(L_TwinIna=1)))) | G7: =IF('Calc'!$H$2+'Calc'!$I$2>0,"",IF('Calc'!$C7="","",SUMPRODUCT((P_StatusN="INACTIVE")*(ISNUMBER(P_LWD))*(P_LWD>='Calc'!$C7)*(P_LWD<EDATE('Calc'!$C7,1))*((P_TypeN="MS")))+SUMPRODUCT((L_StatusN="INACTIVE")*(ISNUMBER(L_LWD))*(L_LWD>='Calc'!$C7)*(L_LWD<EDATE('Calc'!$C7,1))*((L_TypeN="MS")))-SUMPRODUCT((L_StatusN="INACTIVE")*(ISNUMBER(L_LWD))*(L_LWD>='Calc'!$C7)*(L_LWD<EDATE('Calc'!$C7,1))*((L_TypeN="MS"))*(L_InP=1)*(L_TwinIna=1)))) | H7: =IF('Calc'!$H$2+'Calc'!$I$2>0,"",IF('Calc'!$C7="","",SUMPRODUCT((ISNUMBER(P_Start))*(P_Start>='Calc'!$C7)*(P_Start<EDATE('Calc'!$C7,1))*((P_TypeN=UPPER(FiltCat))+(FiltCat="All")))+SUMPRODUCT((ISNUMBER(L_Start))*(L_Start>='Calc'!$C7)*(L_Start<EDATE('Calc'!$C7,1))*((L_TypeN=UPPER(FiltCat))+(FiltCat="All")))-SUMPRODUCT((ISNUMBER(L_Start))*(L_Start>='Calc'!$C7)*(L_Start<EDATE('Calc'!$C7,1))*((L_TypeN=UPPER(FiltCat))+(FiltCat="All"))*(L_InP=1)))) | J7: MS | K7: ='Dashboard'!H$11
B8: =IF('Calc'!$H$2+'Calc'!$I$2>0,"",IF('Calc'!$C8="","",TEXT('Calc'!$C8,"yyyy-mm"))) | C8: =IF('Calc'!$H$2+'Calc'!$I$2>0,"",IF('Calc'!$C8="","",SUMPRODUCT((ISNUMBER(P_Start))*(P_Start<=EOMONTH('Calc'!$C8,0))*(((P_StatusN="ACTIVE")+((ISNUMBER(P_LWD))*(P_LWD>=EOMONTH('Calc'!$C8,0))))>0)*((P_TypeN=UPPER(FiltCat))+(FiltCat="All")))+SUMPRODUCT((ISNUMBER(L_Start))*(L_Start<=EOMONTH('Calc'!$C8,0))*(((L_StatusN="ACTIVE")+((ISNUMBER(L_LWD))*(L_LWD>=EOMONTH('Calc'!$C8,0))))>0)*((L_TypeN=UPPER(FiltCat))+(FiltCat="All")))-SUMPRODUCT((ISNUMBER(L_Start))*(L_Start<=EOMONTH('Calc'!$C8,0))*(((L_StatusN="ACTIVE")+((ISNUMBER(L_LWD))*(L_LWD>=EOMONTH('Calc'!$C8,0))))>0)*((L_TypeN=UPPER(FiltCat))+(FiltCat="All"))*(L_InP=1)))) | D8: =IF('Calc'!$H$2+'Calc'!$I$2>0,"",IF('Calc'!$C8="","",SUMPRODUCT((P_StatusN="INACTIVE")*(ISNUMBER(P_LWD))*(P_LWD>='Calc'!$C8)*(P_LWD<EDATE('Calc'!$C8,1))*((P_TypeN=UPPER(FiltCat))+(FiltCat="All")))+SUMPRODUCT((L_StatusN="INACTIVE")*(ISNUMBER(L_LWD))*(L_LWD>='Calc'!$C8)*(L_LWD<EDATE('Calc'!$C8,1))*((L_TypeN=UPPER(FiltCat))+(FiltCat="All")))-SUMPRODUCT((L_StatusN="INACTIVE")*(ISNUMBER(L_LWD))*(L_LWD>='Calc'!$C8)*(L_LWD<EDATE('Calc'!$C8,1))*((L_TypeN=UPPER(FiltCat))+(FiltCat="All"))*(L_InP=1)*(L_TwinIna=1)))) | E8: =IF('Calc'!$H$2+'Calc'!$I$2>0,"",IF('Calc'!$C8="","",SUMPRODUCT((P_StatusN="INACTIVE")*(ISNUMBER(P_LWD))*(P_LWD>='Calc'!$C8)*(P_LWD<EDATE('Calc'!$C8,1))*((P_TypeN="PERM")))+SUMPRODUCT((L_StatusN="INACTIVE")*(ISNUMBER(L_LWD))*(L_LWD>='Calc'!$C8)*(L_LWD<EDATE('Calc'!$C8,1))*((L_TypeN="PERM")))-SUMPRODUCT((L_StatusN="INACTIVE")*(ISNUMBER(L_LWD))*(L_LWD>='Calc'!$C8)*(L_LWD<EDATE('Calc'!$C8,1))*((L_TypeN="PERM"))*(L_InP=1)*(L_TwinIna=1)))) | F8: =IF('Calc'!$H$2+'Calc'!$I$2>0,"",IF('Calc'!$C8="","",SUMPRODUCT((P_StatusN="INACTIVE")*(ISNUMBER(P_LWD))*(P_LWD>='Calc'!$C8)*(P_LWD<EDATE('Calc'!$C8,1))*((P_TypeN="PC")))+SUMPRODUCT((L_StatusN="INACTIVE")*(ISNUMBER(L_LWD))*(L_LWD>='Calc'!$C8)*(L_LWD<EDATE('Calc'!$C8,1))*((L_TypeN="PC")))-SUMPRODUCT((L_StatusN="INACTIVE")*(ISNUMBER(L_LWD))*(L_LWD>='Calc'!$C8)*(L_LWD<EDATE('Calc'!$C8,1))*((L_TypeN="PC"))*(L_InP=1)*(L_TwinIna=1)))) | G8: =IF('Calc'!$H$2+'Calc'!$I$2>0,"",IF('Calc'!$C8="","",SUMPRODUCT((P_StatusN="INACTIVE")*(ISNUMBER(P_LWD))*(P_LWD>='Calc'!$C8)*(P_LWD<EDATE('Calc'!$C8,1))*((P_TypeN="MS")))+SUMPRODUCT((L_StatusN="INACTIVE")*(ISNUMBER(L_LWD))*(L_LWD>='Calc'!$C8)*(L_LWD<EDATE('Calc'!$C8,1))*((L_TypeN="MS")))-SUMPRODUCT((L_StatusN="INACTIVE")*(ISNUMBER(L_LWD))*(L_LWD>='Calc'!$C8)*(L_LWD<EDATE('Calc'!$C8,1))*((L_TypeN="MS"))*(L_InP=1)*(L_TwinIna=1)))) | H8: =IF('Calc'!$H$2+'Calc'!$I$2>0,"",IF('Calc'!$C8="","",SUMPRODUCT((ISNUMBER(P_Start))*(P_Start>='Calc'!$C8)*(P_Start<EDATE('Calc'!$C8,1))*((P_TypeN=UPPER(FiltCat))+(FiltCat="All")))+SUMPRODUCT((ISNUMBER(L_Start))*(L_Start>='Calc'!$C8)*(L_Start<EDATE('Calc'!$C8,1))*((L_TypeN=UPPER(FiltCat))+(FiltCat="All")))-SUMPRODUCT((ISNUMBER(L_Start))*(L_Start>='Calc'!$C8)*(L_Start<EDATE('Calc'!$C8,1))*((L_TypeN=UPPER(FiltCat))+(FiltCat="All"))*(L_InP=1)))) | J8: Total | K8: =SUM(K5:K7)
B9: =IF('Calc'!$H$2+'Calc'!$I$2>0,"",IF('Calc'!$C9="","",TEXT('Calc'!$C9,"yyyy-mm"))) | C9: =IF('Calc'!$H$2+'Calc'!$I$2>0,"",IF('Calc'!$C9="","",SUMPRODUCT((ISNUMBER(P_Start))*(P_Start<=EOMONTH('Calc'!$C9,0))*(((P_StatusN="ACTIVE")+((ISNUMBER(P_LWD))*(P_LWD>=EOMONTH('Calc'!$C9,0))))>0)*((P_TypeN=UPPER(FiltCat))+(FiltCat="All")))+SUMPRODUCT((ISNUMBER(L_Start))*(L_Start<=EOMONTH('Calc'!$C9,0))*(((L_StatusN="ACTIVE")+((ISNUMBER(L_LWD))*(L_LWD>=EOMONTH('Calc'!$C9,0))))>0)*((L_TypeN=UPPER(FiltCat))+(FiltCat="All")))-SUMPRODUCT((ISNUMBER(L_Start))*(L_Start<=EOMONTH('Calc'!$C9,0))*(((L_StatusN="ACTIVE")+((ISNUMBER(L_LWD))*(L_LWD>=EOMONTH('Calc'!$C9,0))))>0)*((L_TypeN=UPPER(FiltCat))+(FiltCat="All"))*(L_InP=1)))) | D9: =IF('Calc'!$H$2+'Calc'!$I$2>0,"",IF('Calc'!$C9="","",SUMPRODUCT((P_StatusN="INACTIVE")*(ISNUMBER(P_LWD))*(P_LWD>='Calc'!$C9)*(P_LWD<EDATE('Calc'!$C9,1))*((P_TypeN=UPPER(FiltCat))+(FiltCat="All")))+SUMPRODUCT((L_StatusN="INACTIVE")*(ISNUMBER(L_LWD))*(L_LWD>='Calc'!$C9)*(L_LWD<EDATE('Calc'!$C9,1))*((L_TypeN=UPPER(FiltCat))+(FiltCat="All")))-SUMPRODUCT((L_StatusN="INACTIVE")*(ISNUMBER(L_LWD))*(L_LWD>='Calc'!$C9)*(L_LWD<EDATE('Calc'!$C9,1))*((L_TypeN=UPPER(FiltCat))+(FiltCat="All"))*(L_InP=1)*(L_TwinIna=1)))) | E9: =IF('Calc'!$H$2+'Calc'!$I$2>0,"",IF('Calc'!$C9="","",SUMPRODUCT((P_StatusN="INACTIVE")*(ISNUMBER(P_LWD))*(P_LWD>='Calc'!$C9)*(P_LWD<EDATE('Calc'!$C9,1))*((P_TypeN="PERM")))+SUMPRODUCT((L_StatusN="INACTIVE")*(ISNUMBER(L_LWD))*(L_LWD>='Calc'!$C9)*(L_LWD<EDATE('Calc'!$C9,1))*((L_TypeN="PERM")))-SUMPRODUCT((L_StatusN="INACTIVE")*(ISNUMBER(L_LWD))*(L_LWD>='Calc'!$C9)*(L_LWD<EDATE('Calc'!$C9,1))*((L_TypeN="PERM"))*(L_InP=1)*(L_TwinIna=1)))) | F9: =IF('Calc'!$H$2+'Calc'!$I$2>0,"",IF('Calc'!$C9="","",SUMPRODUCT((P_StatusN="INACTIVE")*(ISNUMBER(P_LWD))*(P_LWD>='Calc'!$C9)*(P_LWD<EDATE('Calc'!$C9,1))*((P_TypeN="PC")))+SUMPRODUCT((L_StatusN="INACTIVE")*(ISNUMBER(L_LWD))*(L_LWD>='Calc'!$C9)*(L_LWD<EDATE('Calc'!$C9,1))*((L_TypeN="PC")))-SUMPRODUCT((L_StatusN="INACTIVE")*(ISNUMBER(L_LWD))*(L_LWD>='Calc'!$C9)*(L_LWD<EDATE('Calc'!$C9,1))*((L_TypeN="PC"))*(L_InP=1)*(L_TwinIna=1)))) | G9: =IF('Calc'!$H$2+'Calc'!$I$2>0,"",IF('Calc'!$C9="","",SUMPRODUCT((P_StatusN="INACTIVE")*(ISNUMBER(P_LWD))*(P_LWD>='Calc'!$C9)*(P_LWD<EDATE('Calc'!$C9,1))*((P_TypeN="MS")))+SUMPRODUCT((L_StatusN="INACTIVE")*(ISNUMBER(L_LWD))*(L_LWD>='Calc'!$C9)*(L_LWD<EDATE('Calc'!$C9,1))*((L_TypeN="MS")))-SUMPRODUCT((L_StatusN="INACTIVE")*(ISNUMBER(L_LWD))*(L_LWD>='Calc'!$C9)*(L_LWD<EDATE('Calc'!$C9,1))*((L_TypeN="MS"))*(L_InP=1)*(L_TwinIna=1)))) | H9: =IF('Calc'!$H$2+'Calc'!$I$2>0,"",IF('Calc'!$C9="","",SUMPRODUCT((ISNUMBER(P_Start))*(P_Start>='Calc'!$C9)*(P_Start<EDATE('Calc'!$C9,1))*((P_TypeN=UPPER(FiltCat))+(FiltCat="All")))+SUMPRODUCT((ISNUMBER(L_Start))*(L_Start>='Calc'!$C9)*(L_Start<EDATE('Calc'!$C9,1))*((L_TypeN=UPPER(FiltCat))+(FiltCat="All")))-SUMPRODUCT((ISNUMBER(L_Start))*(L_Start>='Calc'!$C9)*(L_Start<EDATE('Calc'!$C9,1))*((L_TypeN=UPPER(FiltCat))+(FiltCat="All"))*(L_InP=1))))
B10: =IF('Calc'!$H$2+'Calc'!$I$2>0,"",IF('Calc'!$C10="","",TEXT('Calc'!$C10,"yyyy-mm"))) | C10: =IF('Calc'!$H$2+'Calc'!$I$2>0,"",IF('Calc'!$C10="","",SUMPRODUCT((ISNUMBER(P_Start))*(P_Start<=EOMONTH('Calc'!$C10,0))*(((P_StatusN="ACTIVE")+((ISNUMBER(P_LWD))*(P_LWD>=EOMONTH('Calc'!$C10,0))))>0)*((P_TypeN=UPPER(FiltCat))+(FiltCat="All")))+SUMPRODUCT((ISNUMBER(L_Start))*(L_Start<=EOMONTH('Calc'!$C10,0))*(((L_StatusN="ACTIVE")+((ISNUMBER(L_LWD))*(L_LWD>=EOMONTH('Calc'!$C10,0))))>0)*((L_TypeN=UPPER(FiltCat))+(FiltCat="All")))-SUMPRODUCT((ISNUMBER(L_Start))*(L_Start<=EOMONTH('Calc'!$C10,0))*(((L_StatusN="ACTIVE")+((ISNUMBER(L_LWD))*(L_LWD>=EOMONTH('Calc'!$C10,0))))>0)*((L_TypeN=UPPER(FiltCat))+(FiltCat="All"))*(L_InP=1)))) | D10: =IF('Calc'!$H$2+'Calc'!$I$2>0,"",IF('Calc'!$C10="","",SUMPRODUCT((P_StatusN="INACTIVE")*(ISNUMBER(P_LWD))*(P_LWD>='Calc'!$C10)*(P_LWD<EDATE('Calc'!$C10,1))*((P_TypeN=UPPER(FiltCat))+(FiltCat="All")))+SUMPRODUCT((L_StatusN="INACTIVE")*(ISNUMBER(L_LWD))*(L_LWD>='Calc'!$C10)*(L_LWD<EDATE('Calc'!$C10,1))*((L_TypeN=UPPER(FiltCat))+(FiltCat="All")))-SUMPRODUCT((L_StatusN="INACTIVE")*(ISNUMBER(L_LWD))*(L_LWD>='Calc'!$C10)*(L_LWD<EDATE('Calc'!$C10,1))*((L_TypeN=UPPER(FiltCat))+(FiltCat="All"))*(L_InP=1)*(L_TwinIna=1)))) | E10: =IF('Calc'!$H$2+'Calc'!$I$2>0,"",IF('Calc'!$C10="","",SUMPRODUCT((P_StatusN="INACTIVE")*(ISNUMBER(P_LWD))*(P_LWD>='Calc'!$C10)*(P_LWD<EDATE('Calc'!$C10,1))*((P_TypeN="PERM")))+SUMPRODUCT((L_StatusN="INACTIVE")*(ISNUMBER(L_LWD))*(L_LWD>='Calc'!$C10)*(L_LWD<EDATE('Calc'!$C10,1))*((L_TypeN="PERM")))-SUMPRODUCT((L_StatusN="INACTIVE")*(ISNUMBER(L_LWD))*(L_LWD>='Calc'!$C10)*(L_LWD<EDATE('Calc'!$C10,1))*((L_TypeN="PERM"))*(L_InP=1)*(L_TwinIna=1)))) | F10: =IF('Calc'!$H$2+'Calc'!$I$2>0,"",IF('Calc'!$C10="","",SUMPRODUCT((P_StatusN="INACTIVE")*(ISNUMBER(P_LWD))*(P_LWD>='Calc'!$C10)*(P_LWD<EDATE('Calc'!$C10,1))*((P_TypeN="PC")))+SUMPRODUCT((L_StatusN="INACTIVE")*(ISNUMBER(L_LWD))*(L_LWD>='Calc'!$C10)*(L_LWD<EDATE('Calc'!$C10,1))*((L_TypeN="PC")))-SUMPRODUCT((L_StatusN="INACTIVE")*(ISNUMBER(L_LWD))*(L_LWD>='Calc'!$C10)*(L_LWD<EDATE('Calc'!$C10,1))*((L_TypeN="PC"))*(L_InP=1)*(L_TwinIna=1)))) | G10: =IF('Calc'!$H$2+'Calc'!$I$2>0,"",IF('Calc'!$C10="","",SUMPRODUCT((P_StatusN="INACTIVE")*(ISNUMBER(P_LWD))*(P_LWD>='Calc'!$C10)*(P_LWD<EDATE('Calc'!$C10,1))*((P_TypeN="MS")))+SUMPRODUCT((L_StatusN="INACTIVE")*(ISNUMBER(L_LWD))*(L_LWD>='Calc'!$C10)*(L_LWD<EDATE('Calc'!$C10,1))*((L_TypeN="MS")))-SUMPRODUCT((L_StatusN="INACTIVE")*(ISNUMBER(L_LWD))*(L_LWD>='Calc'!$C10)*(L_LWD<EDATE('Calc'!$C10,1))*((L_TypeN="MS"))*(L_InP=1)*(L_TwinIna=1)))) | H10: =IF('Calc'!$H$2+'Calc'!$I$2>0,"",IF('Calc'!$C10="","",SUMPRODUCT((ISNUMBER(P_Start))*(P_Start>='Calc'!$C10)*(P_Start<EDATE('Calc'!$C10,1))*((P_TypeN=UPPER(FiltCat))+(FiltCat="All")))+SUMPRODUCT((ISNUMBER(L_Start))*(L_Start>='Calc'!$C10)*(L_Start<EDATE('Calc'!$C10,1))*((L_TypeN=UPPER(FiltCat))+(FiltCat="All")))-SUMPRODUCT((ISNUMBER(L_Start))*(L_Start>='Calc'!$C10)*(L_Start<EDATE('Calc'!$C10,1))*((L_TypeN=UPPER(FiltCat))+(FiltCat="All"))*(L_InP=1)))) | J10: Referenced by the pie chart - do not delete
B11: =IF('Calc'!$H$2+'Calc'!$I$2>0,"",IF('Calc'!$C11="","",TEXT('Calc'!$C11,"yyyy-mm"))) | C11: =IF('Calc'!$H$2+'Calc'!$I$2>0,"",IF('Calc'!$C11="","",SUMPRODUCT((ISNUMBER(P_Start))*(P_Start<=EOMONTH('Calc'!$C11,0))*(((P_StatusN="ACTIVE")+((ISNUMBER(P_LWD))*(P_LWD>=EOMONTH('Calc'!$C11,0))))>0)*((P_TypeN=UPPER(FiltCat))+(FiltCat="All")))+SUMPRODUCT((ISNUMBER(L_Start))*(L_Start<=EOMONTH('Calc'!$C11,0))*(((L_StatusN="ACTIVE")+((ISNUMBER(L_LWD))*(L_LWD>=EOMONTH('Calc'!$C11,0))))>0)*((L_TypeN=UPPER(FiltCat))+(FiltCat="All")))-SUMPRODUCT((ISNUMBER(L_Start))*(L_Start<=EOMONTH('Calc'!$C11,0))*(((L_StatusN="ACTIVE")+((ISNUMBER(L_LWD))*(L_LWD>=EOMONTH('Calc'!$C11,0))))>0)*((L_TypeN=UPPER(FiltCat))+(FiltCat="All"))*(L_InP=1)))) | D11: =IF('Calc'!$H$2+'Calc'!$I$2>0,"",IF('Calc'!$C11="","",SUMPRODUCT((P_StatusN="INACTIVE")*(ISNUMBER(P_LWD))*(P_LWD>='Calc'!$C11)*(P_LWD<EDATE('Calc'!$C11,1))*((P_TypeN=UPPER(FiltCat))+(FiltCat="All")))+SUMPRODUCT((L_StatusN="INACTIVE")*(ISNUMBER(L_LWD))*(L_LWD>='Calc'!$C11)*(L_LWD<EDATE('Calc'!$C11,1))*((L_TypeN=UPPER(FiltCat))+(FiltCat="All")))-SUMPRODUCT((L_StatusN="INACTIVE")*(ISNUMBER(L_LWD))*(L_LWD>='Calc'!$C11)*(L_LWD<EDATE('Calc'!$C11,1))*((L_TypeN=UPPER(FiltCat))+(FiltCat="All"))*(L_InP=1)*(L_TwinIna=1)))) | E11: =IF('Calc'!$H$2+'Calc'!$I$2>0,"",IF('Calc'!$C11="","",SUMPRODUCT((P_StatusN="INACTIVE")*(ISNUMBER(P_LWD))*(P_LWD>='Calc'!$C11)*(P_LWD<EDATE('Calc'!$C11,1))*((P_TypeN="PERM")))+SUMPRODUCT((L_StatusN="INACTIVE")*(ISNUMBER(L_LWD))*(L_LWD>='Calc'!$C11)*(L_LWD<EDATE('Calc'!$C11,1))*((L_TypeN="PERM")))-SUMPRODUCT((L_StatusN="INACTIVE")*(ISNUMBER(L_LWD))*(L_LWD>='Calc'!$C11)*(L_LWD<EDATE('Calc'!$C11,1))*((L_TypeN="PERM"))*(L_InP=1)*(L_TwinIna=1)))) | F11: =IF('Calc'!$H$2+'Calc'!$I$2>0,"",IF('Calc'!$C11="","",SUMPRODUCT((P_StatusN="INACTIVE")*(ISNUMBER(P_LWD))*(P_LWD>='Calc'!$C11)*(P_LWD<EDATE('Calc'!$C11,1))*((P_TypeN="PC")))+SUMPRODUCT((L_StatusN="INACTIVE")*(ISNUMBER(L_LWD))*(L_LWD>='Calc'!$C11)*(L_LWD<EDATE('Calc'!$C11,1))*((L_TypeN="PC")))-SUMPRODUCT((L_StatusN="INACTIVE")*(ISNUMBER(L_LWD))*(L_LWD>='Calc'!$C11)*(L_LWD<EDATE('Calc'!$C11,1))*((L_TypeN="PC"))*(L_InP=1)*(L_TwinIna=1)))) | G11: =IF('Calc'!$H$2+'Calc'!$I$2>0,"",IF('Calc'!$C11="","",SUMPRODUCT((P_StatusN="INACTIVE")*(ISNUMBER(P_LWD))*(P_LWD>='Calc'!$C11)*(P_LWD<EDATE('Calc'!$C11,1))*((P_TypeN="MS")))+SUMPRODUCT((L_StatusN="INACTIVE")*(ISNUMBER(L_LWD))*(L_LWD>='Calc'!$C11)*(L_LWD<EDATE('Calc'!$C11,1))*((L_TypeN="MS")))-SUMPRODUCT((L_StatusN="INACTIVE")*(ISNUMBER(L_LWD))*(L_LWD>='Calc'!$C11)*(L_LWD<EDATE('Calc'!$C11,1))*((L_TypeN="MS"))*(L_InP=1)*(L_TwinIna=1)))) | H11: =IF('Calc'!$H$2+'Calc'!$I$2>0,"",IF('Calc'!$C11="","",SUMPRODUCT((ISNUMBER(P_Start))*(P_Start>='Calc'!$C11)*(P_Start<EDATE('Calc'!$C11,1))*((P_TypeN=UPPER(FiltCat))+(FiltCat="All")))+SUMPRODUCT((ISNUMBER(L_Start))*(L_Start>='Calc'!$C11)*(L_Start<EDATE('Calc'!$C11,1))*((L_TypeN=UPPER(FiltCat))+(FiltCat="All")))-SUMPRODUCT((ISNUMBER(L_Start))*(L_Start>='Calc'!$C11)*(L_Start<EDATE('Calc'!$C11,1))*((L_TypeN=UPPER(FiltCat))+(FiltCat="All"))*(L_InP=1))))
B12: =IF('Calc'!$H$2+'Calc'!$I$2>0,"",IF('Calc'!$C12="","",TEXT('Calc'!$C12,"yyyy-mm"))) | C12: =IF('Calc'!$H$2+'Calc'!$I$2>0,"",IF('Calc'!$C12="","",SUMPRODUCT((ISNUMBER(P_Start))*(P_Start<=EOMONTH('Calc'!$C12,0))*(((P_StatusN="ACTIVE")+((ISNUMBER(P_LWD))*(P_LWD>=EOMONTH('Calc'!$C12,0))))>0)*((P_TypeN=UPPER(FiltCat))+(FiltCat="All")))+SUMPRODUCT((ISNUMBER(L_Start))*(L_Start<=EOMONTH('Calc'!$C12,0))*(((L_StatusN="ACTIVE")+((ISNUMBER(L_LWD))*(L_LWD>=EOMONTH('Calc'!$C12,0))))>0)*((L_TypeN=UPPER(FiltCat))+(FiltCat="All")))-SUMPRODUCT((ISNUMBER(L_Start))*(L_Start<=EOMONTH('Calc'!$C12,0))*(((L_StatusN="ACTIVE")+((ISNUMBER(L_LWD))*(L_LWD>=EOMONTH('Calc'!$C12,0))))>0)*((L_TypeN=UPPER(FiltCat))+(FiltCat="All"))*(L_InP=1)))) | D12: =IF('Calc'!$H$2+'Calc'!$I$2>0,"",IF('Calc'!$C12="","",SUMPRODUCT((P_StatusN="INACTIVE")*(ISNUMBER(P_LWD))*(P_LWD>='Calc'!$C12)*(P_LWD<EDATE('Calc'!$C12,1))*((P_TypeN=UPPER(FiltCat))+(FiltCat="All")))+SUMPRODUCT((L_StatusN="INACTIVE")*(ISNUMBER(L_LWD))*(L_LWD>='Calc'!$C12)*(L_LWD<EDATE('Calc'!$C12,1))*((L_TypeN=UPPER(FiltCat))+(FiltCat="All")))-SUMPRODUCT((L_StatusN="INACTIVE")*(ISNUMBER(L_LWD))*(L_LWD>='Calc'!$C12)*(L_LWD<EDATE('Calc'!$C12,1))*((L_TypeN=UPPER(FiltCat))+(FiltCat="All"))*(L_InP=1)*(L_TwinIna=1)))) | E12: =IF('Calc'!$H$2+'Calc'!$I$2>0,"",IF('Calc'!$C12="","",SUMPRODUCT((P_StatusN="INACTIVE")*(ISNUMBER(P_LWD))*(P_LWD>='Calc'!$C12)*(P_LWD<EDATE('Calc'!$C12,1))*((P_TypeN="PERM")))+SUMPRODUCT((L_StatusN="INACTIVE")*(ISNUMBER(L_LWD))*(L_LWD>='Calc'!$C12)*(L_LWD<EDATE('Calc'!$C12,1))*((L_TypeN="PERM")))-SUMPRODUCT((L_StatusN="INACTIVE")*(ISNUMBER(L_LWD))*(L_LWD>='Calc'!$C12)*(L_LWD<EDATE('Calc'!$C12,1))*((L_TypeN="PERM"))*(L_InP=1)*(L_TwinIna=1)))) | F12: =IF('Calc'!$H$2+'Calc'!$I$2>0,"",IF('Calc'!$C12="","",SUMPRODUCT((P_StatusN="INACTIVE")*(ISNUMBER(P_LWD))*(P_LWD>='Calc'!$C12)*(P_LWD<EDATE('Calc'!$C12,1))*((P_TypeN="PC")))+SUMPRODUCT((L_StatusN="INACTIVE")*(ISNUMBER(L_LWD))*(L_LWD>='Calc'!$C12)*(L_LWD<EDATE('Calc'!$C12,1))*((L_TypeN="PC")))-SUMPRODUCT((L_StatusN="INACTIVE")*(ISNUMBER(L_LWD))*(L_LWD>='Calc'!$C12)*(L_LWD<EDATE('Calc'!$C12,1))*((L_TypeN="PC"))*(L_InP=1)*(L_TwinIna=1)))) | G12: =IF('Calc'!$H$2+'Calc'!$I$2>0,"",IF('Calc'!$C12="","",SUMPRODUCT((P_StatusN="INACTIVE")*(ISNUMBER(P_LWD))*(P_LWD>='Calc'!$C12)*(P_LWD<EDATE('Calc'!$C12,1))*((P_TypeN="MS")))+SUMPRODUCT((L_StatusN="INACTIVE")*(ISNUMBER(L_LWD))*(L_LWD>='Calc'!$C12)*(L_LWD<EDATE('Calc'!$C12,1))*((L_TypeN="MS")))-SUMPRODUCT((L_StatusN="INACTIVE")*(ISNUMBER(L_LWD))*(L_LWD>='Calc'!$C12)*(L_LWD<EDATE('Calc'!$C12,1))*((L_TypeN="MS"))*(L_InP=1)*(L_TwinIna=1)))) | H12: =IF('Calc'!$H$2+'Calc'!$I$2>0,"",IF('Calc'!$C12="","",SUMPRODUCT((ISNUMBER(P_Start))*(P_Start>='Calc'!$C12)*(P_Start<EDATE('Calc'!$C12,1))*((P_TypeN=UPPER(FiltCat))+(FiltCat="All")))+SUMPRODUCT((ISNUMBER(L_Start))*(L_Start>='Calc'!$C12)*(L_Start<EDATE('Calc'!$C12,1))*((L_TypeN=UPPER(FiltCat))+(FiltCat="All")))-SUMPRODUCT((ISNUMBER(L_Start))*(L_Start>='Calc'!$C12)*(L_Start<EDATE('Calc'!$C12,1))*((L_TypeN=UPPER(FiltCat))+(FiltCat="All"))*(L_InP=1))))
B13: =IF('Calc'!$H$2+'Calc'!$I$2>0,"",IF('Calc'!$C13="","",TEXT('Calc'!$C13,"yyyy-mm"))) | C13: =IF('Calc'!$H$2+'Calc'!$I$2>0,"",IF('Calc'!$C13="","",SUMPRODUCT((ISNUMBER(P_Start))*(P_Start<=EOMONTH('Calc'!$C13,0))*(((P_StatusN="ACTIVE")+((ISNUMBER(P_LWD))*(P_LWD>=EOMONTH('Calc'!$C13,0))))>0)*((P_TypeN=UPPER(FiltCat))+(FiltCat="All")))+SUMPRODUCT((ISNUMBER(L_Start))*(L_Start<=EOMONTH('Calc'!$C13,0))*(((L_StatusN="ACTIVE")+((ISNUMBER(L_LWD))*(L_LWD>=EOMONTH('Calc'!$C13,0))))>0)*((L_TypeN=UPPER(FiltCat))+(FiltCat="All")))-SUMPRODUCT((ISNUMBER(L_Start))*(L_Start<=EOMONTH('Calc'!$C13,0))*(((L_StatusN="ACTIVE")+((ISNUMBER(L_LWD))*(L_LWD>=EOMONTH('Calc'!$C13,0))))>0)*((L_TypeN=UPPER(FiltCat))+(FiltCat="All"))*(L_InP=1)))) | D13: =IF('Calc'!$H$2+'Calc'!$I$2>0,"",IF('Calc'!$C13="","",SUMPRODUCT((P_StatusN="INACTIVE")*(ISNUMBER(P_LWD))*(P_LWD>='Calc'!$C13)*(P_LWD<EDATE('Calc'!$C13,1))*((P_TypeN=UPPER(FiltCat))+(FiltCat="All")))+SUMPRODUCT((L_StatusN="INACTIVE")*(ISNUMBER(L_LWD))*(L_LWD>='Calc'!$C13)*(L_LWD<EDATE('Calc'!$C13,1))*((L_TypeN=UPPER(FiltCat))+(FiltCat="All")))-SUMPRODUCT((L_StatusN="INACTIVE")*(ISNUMBER(L_LWD))*(L_LWD>='Calc'!$C13)*(L_LWD<EDATE('Calc'!$C13,1))*((L_TypeN=UPPER(FiltCat))+(FiltCat="All"))*(L_InP=1)*(L_TwinIna=1)))) | E13: =IF('Calc'!$H$2+'Calc'!$I$2>0,"",IF('Calc'!$C13="","",SUMPRODUCT((P_StatusN="INACTIVE")*(ISNUMBER(P_LWD))*(P_LWD>='Calc'!$C13)*(P_LWD<EDATE('Calc'!$C13,1))*((P_TypeN="PERM")))+SUMPRODUCT((L_StatusN="INACTIVE")*(ISNUMBER(L_LWD))*(L_LWD>='Calc'!$C13)*(L_LWD<EDATE('Calc'!$C13,1))*((L_TypeN="PERM")))-SUMPRODUCT((L_StatusN="INACTIVE")*(ISNUMBER(L_LWD))*(L_LWD>='Calc'!$C13)*(L_LWD<EDATE('Calc'!$C13,1))*((L_TypeN="PERM"))*(L_InP=1)*(L_TwinIna=1)))) | F13: =IF('Calc'!$H$2+'Calc'!$I$2>0,"",IF('Calc'!$C13="","",SUMPRODUCT((P_StatusN="INACTIVE")*(ISNUMBER(P_LWD))*(P_LWD>='Calc'!$C13)*(P_LWD<EDATE('Calc'!$C13,1))*((P_TypeN="PC")))+SUMPRODUCT((L_StatusN="INACTIVE")*(ISNUMBER(L_LWD))*(L_LWD>='Calc'!$C13)*(L_LWD<EDATE('Calc'!$C13,1))*((L_TypeN="PC")))-SUMPRODUCT((L_StatusN="INACTIVE")*(ISNUMBER(L_LWD))*(L_LWD>='Calc'!$C13)*(L_LWD<EDATE('Calc'!$C13,1))*((L_TypeN="PC"))*(L_InP=1)*(L_TwinIna=1)))) | G13: =IF('Calc'!$H$2+'Calc'!$I$2>0,"",IF('Calc'!$C13="","",SUMPRODUCT((P_StatusN="INACTIVE")*(ISNUMBER(P_LWD))*(P_LWD>='Calc'!$C13)*(P_LWD<EDATE('Calc'!$C13,1))*((P_TypeN="MS")))+SUMPRODUCT((L_StatusN="INACTIVE")*(ISNUMBER(L_LWD))*(L_LWD>='Calc'!$C13)*(L_LWD<EDATE('Calc'!$C13,1))*((L_TypeN="MS")))-SUMPRODUCT((L_StatusN="INACTIVE")*(ISNUMBER(L_LWD))*(L_LWD>='Calc'!$C13)*(L_LWD<EDATE('Calc'!$C13,1))*((L_TypeN="MS"))*(L_InP=1)*(L_TwinIna=1)))) | H13: =IF('Calc'!$H$2+'Calc'!$I$2>0,"",IF('Calc'!$C13="","",SUMPRODUCT((ISNUMBER(P_Start))*(P_Start>='Calc'!$C13)*(P_Start<EDATE('Calc'!$C13,1))*((P_TypeN=UPPER(FiltCat))+(FiltCat="All")))+SUMPRODUCT((ISNUMBER(L_Start))*(L_Start>='Calc'!$C13)*(L_Start<EDATE('Calc'!$C13,1))*((L_TypeN=UPPER(FiltCat))+(FiltCat="All")))-SUMPRODUCT((ISNUMBER(L_Start))*(L_Start>='Calc'!$C13)*(L_Start<EDATE('Calc'!$C13,1))*((L_TypeN=UPPER(FiltCat))+(FiltCat="All"))*(L_InP=1))))
B14: =IF('Calc'!$H$2+'Calc'!$I$2>0,"",IF('Calc'!$C14="","",TEXT('Calc'!$C14,"yyyy-mm"))) | C14: =IF('Calc'!$H$2+'Calc'!$I$2>0,"",IF('Calc'!$C14="","",SUMPRODUCT((ISNUMBER(P_Start))*(P_Start<=EOMONTH('Calc'!$C14,0))*(((P_StatusN="ACTIVE")+((ISNUMBER(P_LWD))*(P_LWD>=EOMONTH('Calc'!$C14,0))))>0)*((P_TypeN=UPPER(FiltCat))+(FiltCat="All")))+SUMPRODUCT((ISNUMBER(L_Start))*(L_Start<=EOMONTH('Calc'!$C14,0))*(((L_StatusN="ACTIVE")+((ISNUMBER(L_LWD))*(L_LWD>=EOMONTH('Calc'!$C14,0))))>0)*((L_TypeN=UPPER(FiltCat))+(FiltCat="All")))-SUMPRODUCT((ISNUMBER(L_Start))*(L_Start<=EOMONTH('Calc'!$C14,0))*(((L_StatusN="ACTIVE")+((ISNUMBER(L_LWD))*(L_LWD>=EOMONTH('Calc'!$C14,0))))>0)*((L_TypeN=UPPER(FiltCat))+(FiltCat="All"))*(L_InP=1)))) | D14: =IF('Calc'!$H$2+'Calc'!$I$2>0,"",IF('Calc'!$C14="","",SUMPRODUCT((P_StatusN="INACTIVE")*(ISNUMBER(P_LWD))*(P_LWD>='Calc'!$C14)*(P_LWD<EDATE('Calc'!$C14,1))*((P_TypeN=UPPER(FiltCat))+(FiltCat="All")))+SUMPRODUCT((L_StatusN="INACTIVE")*(ISNUMBER(L_LWD))*(L_LWD>='Calc'!$C14)*(L_LWD<EDATE('Calc'!$C14,1))*((L_TypeN=UPPER(FiltCat))+(FiltCat="All")))-SUMPRODUCT((L_StatusN="INACTIVE")*(ISNUMBER(L_LWD))*(L_LWD>='Calc'!$C14)*(L_LWD<EDATE('Calc'!$C14,1))*((L_TypeN=UPPER(FiltCat))+(FiltCat="All"))*(L_InP=1)*(L_TwinIna=1)))) | E14: =IF('Calc'!$H$2+'Calc'!$I$2>0,"",IF('Calc'!$C14="","",SUMPRODUCT((P_StatusN="INACTIVE")*(ISNUMBER(P_LWD))*(P_LWD>='Calc'!$C14)*(P_LWD<EDATE('Calc'!$C14,1))*((P_TypeN="PERM")))+SUMPRODUCT((L_StatusN="INACTIVE")*(ISNUMBER(L_LWD))*(L_LWD>='Calc'!$C14)*(L_LWD<EDATE('Calc'!$C14,1))*((L_TypeN="PERM")))-SUMPRODUCT((L_StatusN="INACTIVE")*(ISNUMBER(L_LWD))*(L_LWD>='Calc'!$C14)*(L_LWD<EDATE('Calc'!$C14,1))*((L_TypeN="PERM"))*(L_InP=1)*(L_TwinIna=1)))) | F14: =IF('Calc'!$H$2+'Calc'!$I$2>0,"",IF('Calc'!$C14="","",SUMPRODUCT((P_StatusN="INACTIVE")*(ISNUMBER(P_LWD))*(P_LWD>='Calc'!$C14)*(P_LWD<EDATE('Calc'!$C14,1))*((P_TypeN="PC")))+SUMPRODUCT((L_StatusN="INACTIVE")*(ISNUMBER(L_LWD))*(L_LWD>='Calc'!$C14)*(L_LWD<EDATE('Calc'!$C14,1))*((L_TypeN="PC")))-SUMPRODUCT((L_StatusN="INACTIVE")*(ISNUMBER(L_LWD))*(L_LWD>='Calc'!$C14)*(L_LWD<EDATE('Calc'!$C14,1))*((L_TypeN="PC"))*(L_InP=1)*(L_TwinIna=1)))) | G14: =IF('Calc'!$H$2+'Calc'!$I$2>0,"",IF('Calc'!$C14="","",SUMPRODUCT((P_StatusN="INACTIVE")*(ISNUMBER(P_LWD))*(P_LWD>='Calc'!$C14)*(P_LWD<EDATE('Calc'!$C14,1))*((P_TypeN="MS")))+SUMPRODUCT((L_StatusN="INACTIVE")*(ISNUMBER(L_LWD))*(L_LWD>='Calc'!$C14)*(L_LWD<EDATE('Calc'!$C14,1))*((L_TypeN="MS")))-SUMPRODUCT((L_StatusN="INACTIVE")*(ISNUMBER(L_LWD))*(L_LWD>='Calc'!$C14)*(L_LWD<EDATE('Calc'!$C14,1))*((L_TypeN="MS"))*(L_InP=1)*(L_TwinIna=1)))) | H14: =IF('Calc'!$H$2+'Calc'!$I$2>0,"",IF('Calc'!$C14="","",SUMPRODUCT((ISNUMBER(P_Start))*(P_Start>='Calc'!$C14)*(P_Start<EDATE('Calc'!$C14,1))*((P_TypeN=UPPER(FiltCat))+(FiltCat="All")))+SUMPRODUCT((ISNUMBER(L_Start))*(L_Start>='Calc'!$C14)*(L_Start<EDATE('Calc'!$C14,1))*((L_TypeN=UPPER(FiltCat))+(FiltCat="All")))-SUMPRODUCT((ISNUMBER(L_Start))*(L_Start>='Calc'!$C14)*(L_Start<EDATE('Calc'!$C14,1))*((L_TypeN=UPPER(FiltCat))+(FiltCat="All"))*(L_InP=1))))
B15: =IF('Calc'!$H$2+'Calc'!$I$2>0,"",IF('Calc'!$C15="","",TEXT('Calc'!$C15,"yyyy-mm"))) | C15: =IF('Calc'!$H$2+'Calc'!$I$2>0,"",IF('Calc'!$C15="","",SUMPRODUCT((ISNUMBER(P_Start))*(P_Start<=EOMONTH('Calc'!$C15,0))*(((P_StatusN="ACTIVE")+((ISNUMBER(P_LWD))*(P_LWD>=EOMONTH('Calc'!$C15,0))))>0)*((P_TypeN=UPPER(FiltCat))+(FiltCat="All")))+SUMPRODUCT((ISNUMBER(L_Start))*(L_Start<=EOMONTH('Calc'!$C15,0))*(((L_StatusN="ACTIVE")+((ISNUMBER(L_LWD))*(L_LWD>=EOMONTH('Calc'!$C15,0))))>0)*((L_TypeN=UPPER(FiltCat))+(FiltCat="All")))-SUMPRODUCT((ISNUMBER(L_Start))*(L_Start<=EOMONTH('Calc'!$C15,0))*(((L_StatusN="ACTIVE")+((ISNUMBER(L_LWD))*(L_LWD>=EOMONTH('Calc'!$C15,0))))>0)*((L_TypeN=UPPER(FiltCat))+(FiltCat="All"))*(L_InP=1)))) | D15: =IF('Calc'!$H$2+'Calc'!$I$2>0,"",IF('Calc'!$C15="","",SUMPRODUCT((P_StatusN="INACTIVE")*(ISNUMBER(P_LWD))*(P_LWD>='Calc'!$C15)*(P_LWD<EDATE('Calc'!$C15,1))*((P_TypeN=UPPER(FiltCat))+(FiltCat="All")))+SUMPRODUCT((L_StatusN="INACTIVE")*(ISNUMBER(L_LWD))*(L_LWD>='Calc'!$C15)*(L_LWD<EDATE('Calc'!$C15,1))*((L_TypeN=UPPER(FiltCat))+(FiltCat="All")))-SUMPRODUCT((L_StatusN="INACTIVE")*(ISNUMBER(L_LWD))*(L_LWD>='Calc'!$C15)*(L_LWD<EDATE('Calc'!$C15,1))*((L_TypeN=UPPER(FiltCat))+(FiltCat="All"))*(L_InP=1)*(L_TwinIna=1)))) | E15: =IF('Calc'!$H$2+'Calc'!$I$2>0,"",IF('Calc'!$C15="","",SUMPRODUCT((P_StatusN="INACTIVE")*(ISNUMBER(P_LWD))*(P_LWD>='Calc'!$C15)*(P_LWD<EDATE('Calc'!$C15,1))*((P_TypeN="PERM")))+SUMPRODUCT((L_StatusN="INACTIVE")*(ISNUMBER(L_LWD))*(L_LWD>='Calc'!$C15)*(L_LWD<EDATE('Calc'!$C15,1))*((L_TypeN="PERM")))-SUMPRODUCT((L_StatusN="INACTIVE")*(ISNUMBER(L_LWD))*(L_LWD>='Calc'!$C15)*(L_LWD<EDATE('Calc'!$C15,1))*((L_TypeN="PERM"))*(L_InP=1)*(L_TwinIna=1)))) | F15: =IF('Calc'!$H$2+'Calc'!$I$2>0,"",IF('Calc'!$C15="","",SUMPRODUCT((P_StatusN="INACTIVE")*(ISNUMBER(P_LWD))*(P_LWD>='Calc'!$C15)*(P_LWD<EDATE('Calc'!$C15,1))*((P_TypeN="PC")))+SUMPRODUCT((L_StatusN="INACTIVE")*(ISNUMBER(L_LWD))*(L_LWD>='Calc'!$C15)*(L_LWD<EDATE('Calc'!$C15,1))*((L_TypeN="PC")))-SUMPRODUCT((L_StatusN="INACTIVE")*(ISNUMBER(L_LWD))*(L_LWD>='Calc'!$C15)*(L_LWD<EDATE('Calc'!$C15,1))*((L_TypeN="PC"))*(L_InP=1)*(L_TwinIna=1)))) | G15: =IF('Calc'!$H$2+'Calc'!$I$2>0,"",IF('Calc'!$C15="","",SUMPRODUCT((P_StatusN="INACTIVE")*(ISNUMBER(P_LWD))*(P_LWD>='Calc'!$C15)*(P_LWD<EDATE('Calc'!$C15,1))*((P_TypeN="MS")))+SUMPRODUCT((L_StatusN="INACTIVE")*(ISNUMBER(L_LWD))*(L_LWD>='Calc'!$C15)*(L_LWD<EDATE('Calc'!$C15,1))*((L_TypeN="MS")))-SUMPRODUCT((L_StatusN="INACTIVE")*(ISNUMBER(L_LWD))*(L_LWD>='Calc'!$C15)*(L_LWD<EDATE('Calc'!$C15,1))*((L_TypeN="MS"))*(L_InP=1)*(L_TwinIna=1)))) | H15: =IF('Calc'!$H$2+'Calc'!$I$2>0,"",IF('Calc'!$C15="","",SUMPRODUCT((ISNUMBER(P_Start))*(P_Start>='Calc'!$C15)*(P_Start<EDATE('Calc'!$C15,1))*((P_TypeN=UPPER(FiltCat))+(FiltCat="All")))+SUMPRODUCT((ISNUMBER(L_Start))*(L_Start>='Calc'!$C15)*(L_Start<EDATE('Calc'!$C15,1))*((L_TypeN=UPPER(FiltCat))+(FiltCat="All")))-SUMPRODUCT((ISNUMBER(L_Start))*(L_Start>='Calc'!$C15)*(L_Start<EDATE('Calc'!$C15,1))*((L_TypeN=UPPER(FiltCat))+(FiltCat="All"))*(L_InP=1))))
B16: =IF('Calc'!$H$2+'Calc'!$I$2>0,"",IF('Calc'!$C16="","",TEXT('Calc'!$C16,"yyyy-mm"))) | C16: =IF('Calc'!$H$2+'Calc'!$I$2>0,"",IF('Calc'!$C16="","",SUMPRODUCT((ISNUMBER(P_Start))*(P_Start<=EOMONTH('Calc'!$C16,0))*(((P_StatusN="ACTIVE")+((ISNUMBER(P_LWD))*(P_LWD>=EOMONTH('Calc'!$C16,0))))>0)*((P_TypeN=UPPER(FiltCat))+(FiltCat="All")))+SUMPRODUCT((ISNUMBER(L_Start))*(L_Start<=EOMONTH('Calc'!$C16,0))*(((L_StatusN="ACTIVE")+((ISNUMBER(L_LWD))*(L_LWD>=EOMONTH('Calc'!$C16,0))))>0)*((L_TypeN=UPPER(FiltCat))+(FiltCat="All")))-SUMPRODUCT((ISNUMBER(L_Start))*(L_Start<=EOMONTH('Calc'!$C16,0))*(((L_StatusN="ACTIVE")+((ISNUMBER(L_LWD))*(L_LWD>=EOMONTH('Calc'!$C16,0))))>0)*((L_TypeN=UPPER(FiltCat))+(FiltCat="All"))*(L_InP=1)))) | D16: =IF('Calc'!$H$2+'Calc'!$I$2>0,"",IF('Calc'!$C16="","",SUMPRODUCT((P_StatusN="INACTIVE")*(ISNUMBER(P_LWD))*(P_LWD>='Calc'!$C16)*(P_LWD<EDATE('Calc'!$C16,1))*((P_TypeN=UPPER(FiltCat))+(FiltCat="All")))+SUMPRODUCT((L_StatusN="INACTIVE")*(ISNUMBER(L_LWD))*(L_LWD>='Calc'!$C16)*(L_LWD<EDATE('Calc'!$C16,1))*((L_TypeN=UPPER(FiltCat))+(FiltCat="All")))-SUMPRODUCT((L_StatusN="INACTIVE")*(ISNUMBER(L_LWD))*(L_LWD>='Calc'!$C16)*(L_LWD<EDATE('Calc'!$C16,1))*((L_TypeN=UPPER(FiltCat))+(FiltCat="All"))*(L_InP=1)*(L_TwinIna=1)))) | E16: =IF('Calc'!$H$2+'Calc'!$I$2>0,"",IF('Calc'!$C16="","",SUMPRODUCT((P_StatusN="INACTIVE")*(ISNUMBER(P_LWD))*(P_LWD>='Calc'!$C16)*(P_LWD<EDATE('Calc'!$C16,1))*((P_TypeN="PERM")))+SUMPRODUCT((L_StatusN="INACTIVE")*(ISNUMBER(L_LWD))*(L_LWD>='Calc'!$C16)*(L_LWD<EDATE('Calc'!$C16,1))*((L_TypeN="PERM")))-SUMPRODUCT((L_StatusN="INACTIVE")*(ISNUMBER(L_LWD))*(L_LWD>='Calc'!$C16)*(L_LWD<EDATE('Calc'!$C16,1))*((L_TypeN="PERM"))*(L_InP=1)*(L_TwinIna=1)))) | F16: =IF('Calc'!$H$2+'Calc'!$I$2>0,"",IF('Calc'!$C16="","",SUMPRODUCT((P_StatusN="INACTIVE")*(ISNUMBER(P_LWD))*(P_LWD>='Calc'!$C16)*(P_LWD<EDATE('Calc'!$C16,1))*((P_TypeN="PC")))+SUMPRODUCT((L_StatusN="INACTIVE")*(ISNUMBER(L_LWD))*(L_LWD>='Calc'!$C16)*(L_LWD<EDATE('Calc'!$C16,1))*((L_TypeN="PC")))-SUMPRODUCT((L_StatusN="INACTIVE")*(ISNUMBER(L_LWD))*(L_LWD>='Calc'!$C16)*(L_LWD<EDATE('Calc'!$C16,1))*((L_TypeN="PC"))*(L_InP=1)*(L_TwinIna=1)))) | G16: =IF('Calc'!$H$2+'Calc'!$I$2>0,"",IF('Calc'!$C16="","",SUMPRODUCT((P_StatusN="INACTIVE")*(ISNUMBER(P_LWD))*(P_LWD>='Calc'!$C16)*(P_LWD<EDATE('Calc'!$C16,1))*((P_TypeN="MS")))+SUMPRODUCT((L_StatusN="INACTIVE")*(ISNUMBER(L_LWD))*(L_LWD>='Calc'!$C16)*(L_LWD<EDATE('Calc'!$C16,1))*((L_TypeN="MS")))-SUMPRODUCT((L_StatusN="INACTIVE")*(ISNUMBER(L_LWD))*(L_LWD>='Calc'!$C16)*(L_LWD<EDATE('Calc'!$C16,1))*((L_TypeN="MS"))*(L_InP=1)*(L_TwinIna=1)))) | H16: =IF('Calc'!$H$2+'Calc'!$I$2>0,"",IF('Calc'!$C16="","",SUMPRODUCT((ISNUMBER(P_Start))*(P_Start>='Calc'!$C16)*(P_Start<EDATE('Calc'!$C16,1))*((P_TypeN=UPPER(FiltCat))+(FiltCat="All")))+SUMPRODUCT((ISNUMBER(L_Start))*(L_Start>='Calc'!$C16)*(L_Start<EDATE('Calc'!$C16,1))*((L_TypeN=UPPER(FiltCat))+(FiltCat="All")))-SUMPRODUCT((ISNUMBER(L_Start))*(L_Start>='Calc'!$C16)*(L_Start<EDATE('Calc'!$C16,1))*((L_TypeN=UPPER(FiltCat))+(FiltCat="All"))*(L_InP=1))))
B17: =IF('Calc'!$H$2+'Calc'!$I$2>0,"",IF('Calc'!$C17="","",TEXT('Calc'!$C17,"yyyy-mm"))) | C17: =IF('Calc'!$H$2+'Calc'!$I$2>0,"",IF('Calc'!$C17="","",SUMPRODUCT((ISNUMBER(P_Start))*(P_Start<=EOMONTH('Calc'!$C17,0))*(((P_StatusN="ACTIVE")+((ISNUMBER(P_LWD))*(P_LWD>=EOMONTH('Calc'!$C17,0))))>0)*((P_TypeN=UPPER(FiltCat))+(FiltCat="All")))+SUMPRODUCT((ISNUMBER(L_Start))*(L_Start<=EOMONTH('Calc'!$C17,0))*(((L_StatusN="ACTIVE")+((ISNUMBER(L_LWD))*(L_LWD>=EOMONTH('Calc'!$C17,0))))>0)*((L_TypeN=UPPER(FiltCat))+(FiltCat="All")))-SUMPRODUCT((ISNUMBER(L_Start))*(L_Start<=EOMONTH('Calc'!$C17,0))*(((L_StatusN="ACTIVE")+((ISNUMBER(L_LWD))*(L_LWD>=EOMONTH('Calc'!$C17,0))))>0)*((L_TypeN=UPPER(FiltCat))+(FiltCat="All"))*(L_InP=1)))) | D17: =IF('Calc'!$H$2+'Calc'!$I$2>0,"",IF('Calc'!$C17="","",SUMPRODUCT((P_StatusN="INACTIVE")*(ISNUMBER(P_LWD))*(P_LWD>='Calc'!$C17)*(P_LWD<EDATE('Calc'!$C17,1))*((P_TypeN=UPPER(FiltCat))+(FiltCat="All")))+SUMPRODUCT((L_StatusN="INACTIVE")*(ISNUMBER(L_LWD))*(L_LWD>='Calc'!$C17)*(L_LWD<EDATE('Calc'!$C17,1))*((L_TypeN=UPPER(FiltCat))+(FiltCat="All")))-SUMPRODUCT((L_StatusN="INACTIVE")*(ISNUMBER(L_LWD))*(L_LWD>='Calc'!$C17)*(L_LWD<EDATE('Calc'!$C17,1))*((L_TypeN=UPPER(FiltCat))+(FiltCat="All"))*(L_InP=1)*(L_TwinIna=1)))) | E17: =IF('Calc'!$H$2+'Calc'!$I$2>0,"",IF('Calc'!$C17="","",SUMPRODUCT((P_StatusN="INACTIVE")*(ISNUMBER(P_LWD))*(P_LWD>='Calc'!$C17)*(P_LWD<EDATE('Calc'!$C17,1))*((P_TypeN="PERM")))+SUMPRODUCT((L_StatusN="INACTIVE")*(ISNUMBER(L_LWD))*(L_LWD>='Calc'!$C17)*(L_LWD<EDATE('Calc'!$C17,1))*((L_TypeN="PERM")))-SUMPRODUCT((L_StatusN="INACTIVE")*(ISNUMBER(L_LWD))*(L_LWD>='Calc'!$C17)*(L_LWD<EDATE('Calc'!$C17,1))*((L_TypeN="PERM"))*(L_InP=1)*(L_TwinIna=1)))) | F17: =IF('Calc'!$H$2+'Calc'!$I$2>0,"",IF('Calc'!$C17="","",SUMPRODUCT((P_StatusN="INACTIVE")*(ISNUMBER(P_LWD))*(P_LWD>='Calc'!$C17)*(P_LWD<EDATE('Calc'!$C17,1))*((P_TypeN="PC")))+SUMPRODUCT((L_StatusN="INACTIVE")*(ISNUMBER(L_LWD))*(L_LWD>='Calc'!$C17)*(L_LWD<EDATE('Calc'!$C17,1))*((L_TypeN="PC")))-SUMPRODUCT((L_StatusN="INACTIVE")*(ISNUMBER(L_LWD))*(L_LWD>='Calc'!$C17)*(L_LWD<EDATE('Calc'!$C17,1))*((L_TypeN="PC"))*(L_InP=1)*(L_TwinIna=1)))) | G17: =IF('Calc'!$H$2+'Calc'!$I$2>0,"",IF('Calc'!$C17="","",SUMPRODUCT((P_StatusN="INACTIVE")*(ISNUMBER(P_LWD))*(P_LWD>='Calc'!$C17)*(P_LWD<EDATE('Calc'!$C17,1))*((P_TypeN="MS")))+SUMPRODUCT((L_StatusN="INACTIVE")*(ISNUMBER(L_LWD))*(L_LWD>='Calc'!$C17)*(L_LWD<EDATE('Calc'!$C17,1))*((L_TypeN="MS")))-SUMPRODUCT((L_StatusN="INACTIVE")*(ISNUMBER(L_LWD))*(L_LWD>='Calc'!$C17)*(L_LWD<EDATE('Calc'!$C17,1))*((L_TypeN="MS"))*(L_InP=1)*(L_TwinIna=1)))) | H17: =IF('Calc'!$H$2+'Calc'!$I$2>0,"",IF('Calc'!$C17="","",SUMPRODUCT((ISNUMBER(P_Start))*(P_Start>='Calc'!$C17)*(P_Start<EDATE('Calc'!$C17,1))*((P_TypeN=UPPER(FiltCat))+(FiltCat="All")))+SUMPRODUCT((ISNUMBER(L_Start))*(L_Start>='Calc'!$C17)*(L_Start<EDATE('Calc'!$C17,1))*((L_TypeN=UPPER(FiltCat))+(FiltCat="All")))-SUMPRODUCT((ISNUMBER(L_Start))*(L_Start>='Calc'!$C17)*(L_Start<EDATE('Calc'!$C17,1))*((L_TypeN=UPPER(FiltCat))+(FiltCat="All"))*(L_InP=1))))
B18: =IF('Calc'!$H$2+'Calc'!$I$2>0,"",IF('Calc'!$C18="","",TEXT('Calc'!$C18,"yyyy-mm"))) | C18: =IF('Calc'!$H$2+'Calc'!$I$2>0,"",IF('Calc'!$C18="","",SUMPRODUCT((ISNUMBER(P_Start))*(P_Start<=EOMONTH('Calc'!$C18,0))*(((P_StatusN="ACTIVE")+((ISNUMBER(P_LWD))*(P_LWD>=EOMONTH('Calc'!$C18,0))))>0)*((P_TypeN=UPPER(FiltCat))+(FiltCat="All")))+SUMPRODUCT((ISNUMBER(L_Start))*(L_Start<=EOMONTH('Calc'!$C18,0))*(((L_StatusN="ACTIVE")+((ISNUMBER(L_LWD))*(L_LWD>=EOMONTH('Calc'!$C18,0))))>0)*((L_TypeN=UPPER(FiltCat))+(FiltCat="All")))-SUMPRODUCT((ISNUMBER(L_Start))*(L_Start<=EOMONTH('Calc'!$C18,0))*(((L_StatusN="ACTIVE")+((ISNUMBER(L_LWD))*(L_LWD>=EOMONTH('Calc'!$C18,0))))>0)*((L_TypeN=UPPER(FiltCat))+(FiltCat="All"))*(L_InP=1)))) | D18: =IF('Calc'!$H$2+'Calc'!$I$2>0,"",IF('Calc'!$C18="","",SUMPRODUCT((P_StatusN="INACTIVE")*(ISNUMBER(P_LWD))*(P_LWD>='Calc'!$C18)*(P_LWD<EDATE('Calc'!$C18,1))*((P_TypeN=UPPER(FiltCat))+(FiltCat="All")))+SUMPRODUCT((L_StatusN="INACTIVE")*(ISNUMBER(L_LWD))*(L_LWD>='Calc'!$C18)*(L_LWD<EDATE('Calc'!$C18,1))*((L_TypeN=UPPER(FiltCat))+(FiltCat="All")))-SUMPRODUCT((L_StatusN="INACTIVE")*(ISNUMBER(L_LWD))*(L_LWD>='Calc'!$C18)*(L_LWD<EDATE('Calc'!$C18,1))*((L_TypeN=UPPER(FiltCat))+(FiltCat="All"))*(L_InP=1)*(L_TwinIna=1)))) | E18: =IF('Calc'!$H$2+'Calc'!$I$2>0,"",IF('Calc'!$C18="","",SUMPRODUCT((P_StatusN="INACTIVE")*(ISNUMBER(P_LWD))*(P_LWD>='Calc'!$C18)*(P_LWD<EDATE('Calc'!$C18,1))*((P_TypeN="PERM")))+SUMPRODUCT((L_StatusN="INACTIVE")*(ISNUMBER(L_LWD))*(L_LWD>='Calc'!$C18)*(L_LWD<EDATE('Calc'!$C18,1))*((L_TypeN="PERM")))-SUMPRODUCT((L_StatusN="INACTIVE")*(ISNUMBER(L_LWD))*(L_LWD>='Calc'!$C18)*(L_LWD<EDATE('Calc'!$C18,1))*((L_TypeN="PERM"))*(L_InP=1)*(L_TwinIna=1)))) | F18: =IF('Calc'!$H$2+'Calc'!$I$2>0,"",IF('Calc'!$C18="","",SUMPRODUCT((P_StatusN="INACTIVE")*(ISNUMBER(P_LWD))*(P_LWD>='Calc'!$C18)*(P_LWD<EDATE('Calc'!$C18,1))*((P_TypeN="PC")))+SUMPRODUCT((L_StatusN="INACTIVE")*(ISNUMBER(L_LWD))*(L_LWD>='Calc'!$C18)*(L_LWD<EDATE('Calc'!$C18,1))*((L_TypeN="PC")))-SUMPRODUCT((L_StatusN="INACTIVE")*(ISNUMBER(L_LWD))*(L_LWD>='Calc'!$C18)*(L_LWD<EDATE('Calc'!$C18,1))*((L_TypeN="PC"))*(L_InP=1)*(L_TwinIna=1)))) | G18: =IF('Calc'!$H$2+'Calc'!$I$2>0,"",IF('Calc'!$C18="","",SUMPRODUCT((P_StatusN="INACTIVE")*(ISNUMBER(P_LWD))*(P_LWD>='Calc'!$C18)*(P_LWD<EDATE('Calc'!$C18,1))*((P_TypeN="MS")))+SUMPRODUCT((L_StatusN="INACTIVE")*(ISNUMBER(L_LWD))*(L_LWD>='Calc'!$C18)*(L_LWD<EDATE('Calc'!$C18,1))*((L_TypeN="MS")))-SUMPRODUCT((L_StatusN="INACTIVE")*(ISNUMBER(L_LWD))*(L_LWD>='Calc'!$C18)*(L_LWD<EDATE('Calc'!$C18,1))*((L_TypeN="MS"))*(L_InP=1)*(L_TwinIna=1)))) | H18: =IF('Calc'!$H$2+'Calc'!$I$2>0,"",IF('Calc'!$C18="","",SUMPRODUCT((ISNUMBER(P_Start))*(P_Start>='Calc'!$C18)*(P_Start<EDATE('Calc'!$C18,1))*((P_TypeN=UPPER(FiltCat))+(FiltCat="All")))+SUMPRODUCT((ISNUMBER(L_Start))*(L_Start>='Calc'!$C18)*(L_Start<EDATE('Calc'!$C18,1))*((L_TypeN=UPPER(FiltCat))+(FiltCat="All")))-SUMPRODUCT((ISNUMBER(L_Start))*(L_Start>='Calc'!$C18)*(L_Start<EDATE('Calc'!$C18,1))*((L_TypeN=UPPER(FiltCat))+(FiltCat="All"))*(L_InP=1))))
B19: =IF('Calc'!$H$2+'Calc'!$I$2>0,"",IF('Calc'!$C19="","",TEXT('Calc'!$C19,"yyyy-mm"))) | C19: =IF('Calc'!$H$2+'Calc'!$I$2>0,"",IF('Calc'!$C19="","",SUMPRODUCT((ISNUMBER(P_Start))*(P_Start<=EOMONTH('Calc'!$C19,0))*(((P_StatusN="ACTIVE")+((ISNUMBER(P_LWD))*(P_LWD>=EOMONTH('Calc'!$C19,0))))>0)*((P_TypeN=UPPER(FiltCat))+(FiltCat="All")))+SUMPRODUCT((ISNUMBER(L_Start))*(L_Start<=EOMONTH('Calc'!$C19,0))*(((L_StatusN="ACTIVE")+((ISNUMBER(L_LWD))*(L_LWD>=EOMONTH('Calc'!$C19,0))))>0)*((L_TypeN=UPPER(FiltCat))+(FiltCat="All")))-SUMPRODUCT((ISNUMBER(L_Start))*(L_Start<=EOMONTH('Calc'!$C19,0))*(((L_StatusN="ACTIVE")+((ISNUMBER(L_LWD))*(L_LWD>=EOMONTH('Calc'!$C19,0))))>0)*((L_TypeN=UPPER(FiltCat))+(FiltCat="All"))*(L_InP=1)))) | D19: =IF('Calc'!$H$2+'Calc'!$I$2>0,"",IF('Calc'!$C19="","",SUMPRODUCT((P_StatusN="INACTIVE")*(ISNUMBER(P_LWD))*(P_LWD>='Calc'!$C19)*(P_LWD<EDATE('Calc'!$C19,1))*((P_TypeN=UPPER(FiltCat))+(FiltCat="All")))+SUMPRODUCT((L_StatusN="INACTIVE")*(ISNUMBER(L_LWD))*(L_LWD>='Calc'!$C19)*(L_LWD<EDATE('Calc'!$C19,1))*((L_TypeN=UPPER(FiltCat))+(FiltCat="All")))-SUMPRODUCT((L_StatusN="INACTIVE")*(ISNUMBER(L_LWD))*(L_LWD>='Calc'!$C19)*(L_LWD<EDATE('Calc'!$C19,1))*((L_TypeN=UPPER(FiltCat))+(FiltCat="All"))*(L_InP=1)*(L_TwinIna=1)))) | E19: =IF('Calc'!$H$2+'Calc'!$I$2>0,"",IF('Calc'!$C19="","",SUMPRODUCT((P_StatusN="INACTIVE")*(ISNUMBER(P_LWD))*(P_LWD>='Calc'!$C19)*(P_LWD<EDATE('Calc'!$C19,1))*((P_TypeN="PERM")))+SUMPRODUCT((L_StatusN="INACTIVE")*(ISNUMBER(L_LWD))*(L_LWD>='Calc'!$C19)*(L_LWD<EDATE('Calc'!$C19,1))*((L_TypeN="PERM")))-SUMPRODUCT((L_StatusN="INACTIVE")*(ISNUMBER(L_LWD))*(L_LWD>='Calc'!$C19)*(L_LWD<EDATE('Calc'!$C19,1))*((L_TypeN="PERM"))*(L_InP=1)*(L_TwinIna=1)))) | F19: =IF('Calc'!$H$2+'Calc'!$I$2>0,"",IF('Calc'!$C19="","",SUMPRODUCT((P_StatusN="INACTIVE")*(ISNUMBER(P_LWD))*(P_LWD>='Calc'!$C19)*(P_LWD<EDATE('Calc'!$C19,1))*((P_TypeN="PC")))+SUMPRODUCT((L_StatusN="INACTIVE")*(ISNUMBER(L_LWD))*(L_LWD>='Calc'!$C19)*(L_LWD<EDATE('Calc'!$C19,1))*((L_TypeN="PC")))-SUMPRODUCT((L_StatusN="INACTIVE")*(ISNUMBER(L_LWD))*(L_LWD>='Calc'!$C19)*(L_LWD<EDATE('Calc'!$C19,1))*((L_TypeN="PC"))*(L_InP=1)*(L_TwinIna=1)))) | G19: =IF('Calc'!$H$2+'Calc'!$I$2>0,"",IF('Calc'!$C19="","",SUMPRODUCT((P_StatusN="INACTIVE")*(ISNUMBER(P_LWD))*(P_LWD>='Calc'!$C19)*(P_LWD<EDATE('Calc'!$C19,1))*((P_TypeN="MS")))+SUMPRODUCT((L_StatusN="INACTIVE")*(ISNUMBER(L_LWD))*(L_LWD>='Calc'!$C19)*(L_LWD<EDATE('Calc'!$C19,1))*((L_TypeN="MS")))-SUMPRODUCT((L_StatusN="INACTIVE")*(ISNUMBER(L_LWD))*(L_LWD>='Calc'!$C19)*(L_LWD<EDATE('Calc'!$C19,1))*((L_TypeN="MS"))*(L_InP=1)*(L_TwinIna=1)))) | H19: =IF('Calc'!$H$2+'Calc'!$I$2>0,"",IF('Calc'!$C19="","",SUMPRODUCT((ISNUMBER(P_Start))*(P_Start>='Calc'!$C19)*(P_Start<EDATE('Calc'!$C19,1))*((P_TypeN=UPPER(FiltCat))+(FiltCat="All")))+SUMPRODUCT((ISNUMBER(L_Start))*(L_Start>='Calc'!$C19)*(L_Start<EDATE('Calc'!$C19,1))*((L_TypeN=UPPER(FiltCat))+(FiltCat="All")))-SUMPRODUCT((ISNUMBER(L_Start))*(L_Start>='Calc'!$C19)*(L_Start<EDATE('Calc'!$C19,1))*((L_TypeN=UPPER(FiltCat))+(FiltCat="All"))*(L_InP=1))))
B20: =IF('Calc'!$H$2+'Calc'!$I$2>0,"",IF('Calc'!$C20="","",TEXT('Calc'!$C20,"yyyy-mm"))) | C20: =IF('Calc'!$H$2+'Calc'!$I$2>0,"",IF('Calc'!$C20="","",SUMPRODUCT((ISNUMBER(P_Start))*(P_Start<=EOMONTH('Calc'!$C20,0))*(((P_StatusN="ACTIVE")+((ISNUMBER(P_LWD))*(P_LWD>=EOMONTH('Calc'!$C20,0))))>0)*((P_TypeN=UPPER(FiltCat))+(FiltCat="All")))+SUMPRODUCT((ISNUMBER(L_Start))*(L_Start<=EOMONTH('Calc'!$C20,0))*(((L_StatusN="ACTIVE")+((ISNUMBER(L_LWD))*(L_LWD>=EOMONTH('Calc'!$C20,0))))>0)*((L_TypeN=UPPER(FiltCat))+(FiltCat="All")))-SUMPRODUCT((ISNUMBER(L_Start))*(L_Start<=EOMONTH('Calc'!$C20,0))*(((L_StatusN="ACTIVE")+((ISNUMBER(L_LWD))*(L_LWD>=EOMONTH('Calc'!$C20,0))))>0)*((L_TypeN=UPPER(FiltCat))+(FiltCat="All"))*(L_InP=1)))) | D20: =IF('Calc'!$H$2+'Calc'!$I$2>0,"",IF('Calc'!$C20="","",SUMPRODUCT((P_StatusN="INACTIVE")*(ISNUMBER(P_LWD))*(P_LWD>='Calc'!$C20)*(P_LWD<EDATE('Calc'!$C20,1))*((P_TypeN=UPPER(FiltCat))+(FiltCat="All")))+SUMPRODUCT((L_StatusN="INACTIVE")*(ISNUMBER(L_LWD))*(L_LWD>='Calc'!$C20)*(L_LWD<EDATE('Calc'!$C20,1))*((L_TypeN=UPPER(FiltCat))+(FiltCat="All")))-SUMPRODUCT((L_StatusN="INACTIVE")*(ISNUMBER(L_LWD))*(L_LWD>='Calc'!$C20)*(L_LWD<EDATE('Calc'!$C20,1))*((L_TypeN=UPPER(FiltCat))+(FiltCat="All"))*(L_InP=1)*(L_TwinIna=1)))) | E20: =IF('Calc'!$H$2+'Calc'!$I$2>0,"",IF('Calc'!$C20="","",SUMPRODUCT((P_StatusN="INACTIVE")*(ISNUMBER(P_LWD))*(P_LWD>='Calc'!$C20)*(P_LWD<EDATE('Calc'!$C20,1))*((P_TypeN="PERM")))+SUMPRODUCT((L_StatusN="INACTIVE")*(ISNUMBER(L_LWD))*(L_LWD>='Calc'!$C20)*(L_LWD<EDATE('Calc'!$C20,1))*((L_TypeN="PERM")))-SUMPRODUCT((L_StatusN="INACTIVE")*(ISNUMBER(L_LWD))*(L_LWD>='Calc'!$C20)*(L_LWD<EDATE('Calc'!$C20,1))*((L_TypeN="PERM"))*(L_InP=1)*(L_TwinIna=1)))) | F20: =IF('Calc'!$H$2+'Calc'!$I$2>0,"",IF('Calc'!$C20="","",SUMPRODUCT((P_StatusN="INACTIVE")*(ISNUMBER(P_LWD))*(P_LWD>='Calc'!$C20)*(P_LWD<EDATE('Calc'!$C20,1))*((P_TypeN="PC")))+SUMPRODUCT((L_StatusN="INACTIVE")*(ISNUMBER(L_LWD))*(L_LWD>='Calc'!$C20)*(L_LWD<EDATE('Calc'!$C20,1))*((L_TypeN="PC")))-SUMPRODUCT((L_StatusN="INACTIVE")*(ISNUMBER(L_LWD))*(L_LWD>='Calc'!$C20)*(L_LWD<EDATE('Calc'!$C20,1))*((L_TypeN="PC"))*(L_InP=1)*(L_TwinIna=1)))) | G20: =IF('Calc'!$H$2+'Calc'!$I$2>0,"",IF('Calc'!$C20="","",SUMPRODUCT((P_StatusN="INACTIVE")*(ISNUMBER(P_LWD))*(P_LWD>='Calc'!$C20)*(P_LWD<EDATE('Calc'!$C20,1))*((P_TypeN="MS")))+SUMPRODUCT((L_StatusN="INACTIVE")*(ISNUMBER(L_LWD))*(L_LWD>='Calc'!$C20)*(L_LWD<EDATE('Calc'!$C20,1))*((L_TypeN="MS")))-SUMPRODUCT((L_StatusN="INACTIVE")*(ISNUMBER(L_LWD))*(L_LWD>='Calc'!$C20)*(L_LWD<EDATE('Calc'!$C20,1))*((L_TypeN="MS"))*(L_InP=1)*(L_TwinIna=1)))) | H20: =IF('Calc'!$H$2+'Calc'!$I$2>0,"",IF('Calc'!$C20="","",SUMPRODUCT((ISNUMBER(P_Start))*(P_Start>='Calc'!$C20)*(P_Start<EDATE('Calc'!$C20,1))*((P_TypeN=UPPER(FiltCat))+(FiltCat="All")))+SUMPRODUCT((ISNUMBER(L_Start))*(L_Start>='Calc'!$C20)*(L_Start<EDATE('Calc'!$C20,1))*((L_TypeN=UPPER(FiltCat))+(FiltCat="All")))-SUMPRODUCT((ISNUMBER(L_Start))*(L_Start>='Calc'!$C20)*(L_Start<EDATE('Calc'!$C20,1))*((L_TypeN=UPPER(FiltCat))+(FiltCat="All"))*(L_InP=1))))
